Workbook

Sheet 붙여넣기용
C1: 35000 | G1: 강계순5423
C2: 35000 | G2: 강권종2013
C3: 35000 | G3: 강금옥4252
C4: 35000 | G4: 강두연1222
C5: 35000 | G5: 강민정0333
C6: 35000 | G6: 최인숙2765
C7: 35000 | G7: 강윤진3620
C8: 35000 | G8: 강창숙5339
C9: 35000 | G9: 강철민6334
C10: 35000 | G10: 강평애6138
C11: 35000 | G11: 강향숙1335
C12: 35000 | G12: 강현수8943
... C982: 70000 | G982: KIM DENNIS HO7251

Sheet 1. 신청자리스트
A1: ID | B1: 신청일시 | C1: 이름 | D1: 전화번호 | E1: 생년월일(앞자리) | F1: 티켓수 | G1: 동반자 이름 | H1: 동반자 전화번호 | I1: 동반자 생년월일 | J1: 임시인덱스 | K1: 중복입금여부 | L1: 필요입금액 | M1: 실제입금액 | N1: 환급액
A2: 145 | B2: 2025. 12. 07. 09:06:03 | C2: 김영련 | D2: 010-3661-1199 | E2: 580809 | F2: 2 | G2: 주영혜 | H2: 010-6235-8260 | I2: 540205 | J2: =concatenate(C2,right(D2,4)) -> 김영련1199 | K2: =if(N2=0,"정상","중복") -> 중복 | L2: 70000 | M2: 140000 | N2: 70000 | O2: 필요입금액 | P2: =sum(L:L) -> 50470000
A3: 918 | B3: 2025. 12. 07. 09:07:52 | C3: 최원현 | D3: 010-3000-5775 | E3: 600729 | F3: 2 | G3: 정시유 | H3: 010-3000-5125 | I3: 630403 | J3: =concatenate(C3,right(D3,4)) -> 최원현5775 | K3: =if(N3=0,"정상","중복") -> 중복 | L3: 70000 | M3: 140000 | N3: 70000 | O3: 실입금합계 | P3: =sum('1.신청입금매칭표'!G:G) -> 59500000
A4: 629 | B4: 2025. 12. 07. 09:07:26 | C4: 이유주 | D4: 010-7138-0037 | E4: 640228 | F4: 2 | G4: 손정애 | H4: 010-5591-1926 | I4: 531125 | J4: =concatenate(C4,right(D4,4)) -> 이유주0037 | K4: =if(N4=0,"정상","중복") -> 정상 | L4: 70000 | M4: 70000 | N4: 0 | O4: 환급액 | P4: =sum(N:N) -> 9030000
A5: 319 | B5: 2025. 12. 07. 09:06:49 | C5: 함정순 | D5: 010-8885-5693 | E5: 620819 | F5: 2 | G5: 문현주 | H5: 010-6316-5693 | I5: 890118 | J5: =concatenate(C5,right(D5,4)) -> 함정순5693 | K5: =if(N5=0,"정상","중복") -> 정상 | L5: 70000 | M5: 70000 | N5: 0 | O5: 실입금-환급 | P5: =P3-P4 -> 50470000
A6: 129 | B6: 2025. 12. 07. 09:02:10 | C6: 임기영 | D6: 010-9605-2028 | E6: 810729 | F6: 2 | G6: - | H6: - | I6: - | J6: =concatenate(C6,right(D6,4)) -> 임기영2028 | K6: =if(N6=0,"정상","중복") -> 정상 | L6: 70000 | M6: 70000 | N6: 0
A7: 986 | B7: 2025. 12. 07. 09:07:57 | C7: 민도선 | D7: 010-2806-5057 | E7: 601020 | F7: 2 | G7: 이경민 | H7: 010-5360-3758 | I7: 880223 | J7: =concatenate(C7,right(D7,4)) -> 민도선5057 | K7: =if(N7=0,"정상","중복") -> 중복 | L7: 70000 | M7: 210000 | N7: 140000
A8: 491 | B8: 2025. 12. 07. 09:07:06 | C8: 최숙희 | D8: 010-4801-8576 | E8: 700513 | F8: 2 | G8: 신미자 | H8: 010-3604-1619 | I8: 740720 | J8: =concatenate(C8,right(D8,4)) -> 최숙희8576 | K8: =if(N8=0,"정상","중복") -> 중복 | L8: 70000 | M8: 210000 | N8: 140000
A9: 349 | B9: 2025. 12. 07. 09:06:52 | C9: 정옥화 | D9: 010-5300-5039 | E9: 760218 | F9: 2 | G9: 류제성 | H9: 010-3672-6717 | I9: 880522 | J9: =concatenate(C9,right(D9,4)) -> 정옥화5039 | K9: =if(N9=0,"정상","중복") -> 중복 | L9: 70000 | M9: 210000 | N9: 140000
A10: 416 | B10: 2025. 12. 07. 09:06:59 | C10: 지은자 | D10: 010-4937-5295 | E10: 691025 | F10: 2 | G10: 김해영 | H10: 010-6556-2831 | I10: 691223 | J10: =concatenate(C10,right(D10,4)) -> 지은자5295 | K10: =if(N10=0,"정상","중복") -> 중복 | L10: 70000 | M10: 210000 | N10: 140000
A11: 484 | B11: 2025. 12. 07. 09:07:05 | C11: 안은숙 | D11: 010-2804-5404 | E11: 630208 | F11: 2 | G11: 김종대 | H11: 010-8231-1890 | I11: 610313 | J11: =concatenate(C11,right(D11,4)) -> 안은숙5404 | K11: =if(N11=0,"정상","중복") -> 중복 | L11: 70000 | M11: 210000 | N11: 140000
A12: 1055 | B12: 2025. 12. 07. 09:08:00 | C12: 백은주 | D12: 010-3324-8636 | E12: 620521 | F12: 2 | G12: 김태순 | H12: 010-3238-5025 | I12: 550315 | J12: =concatenate(C12,right(D12,4)) -> 백은주8636 | K12: =if(N12=0,"정상","중복") -> 중복 | L12: 70000 | M12: 200000 | N12: 130000
A13: 336 | B13: 2025. 12. 07. 09:06:51 | C13: 석진순 | D13: 010-4646-8304 | E13: 670202 | F13: 2 | G13: 김필환 | H13: 010-3622-0097 | I13: 600924 | J13: =concatenate(C13,right(D13,4)) -> 석진순8304 | K13: =if(N13=0,"정상","중복") -> 중복 | L13: 70000 | M13: 190000 | N13: 120000
A14: 741 | B14: 2025. 12. 07. 09:07:36 | C14: 김지수 | D14: 010-5008-7210 | E14: 721007 | F14: 2 | G14: 허연희 | H14: 010-2606-7464 | I14: 780112 | J14: =concatenate(C14,right(D14,4)) -> 김지수7210 | K14: =if(N14=0,"정상","중복") -> 중복 | L14: 70000 | M14: 140000 | N14: 70000
A15: 1039 | B15: 2025. 12. 07. 09:07:59 | C15: 김일 | D15: 010-4350-9644 | E15: 630102 | F15: 2 | G15: 한명희 | H15: 010-5632-8863 | I15: 631012 | J15: =concatenate(C15,right(D15,4)) -> 김일9644 | K15: =if(N15=0,"정상","중복") -> 중복 | L15: 70000 | M15: 140000 | N15: 70000
A16: 984 | B16: 2025. 12. 07. 09:07:57 | C16: 차현주 | D16: 010-4512-1480 | E16: 650203 | F16: 2 | G16: 하예진 | H16: 010-5795-1480 | I16: 910215 | J16: =concatenate(C16,right(D16,4)) -> 차현주1480 | K16: =if(N16=0,"정상","중복") -> 중복 | L16: 70000 | M16: 140000 | N16: 70000
A17: 1224 | B17: 2025. 12. 07. 09:08:12 | C17: 윤경숙 | D17: 010-7119-1230 | E17: 580221 | F17: 2 | G17: 최정묵 | H17: 010-7337-2727 | I17: 590407 | J17: =concatenate(C17,right(D17,4)) -> 윤경숙1230 | K17: =if(N17=0,"정상","중복") -> 중복 | L17: 70000 | M17: 140000 | N17: 70000
A18: 1075 | B18: 2025. 12. 07. 09:08:01 | C18: 이혜승 | D18: 010-4184-7794 | E18: 740508 | F18: 2 | G18: 최인자 | H18: 010-4174-4809 | I18: 480914 | J18: =concatenate(C18,right(D18,4)) -> 이혜승7794 | K18: =if(N18=0,"정상","중복") -> 중복 | L18: 70000 | M18: 140000 | N18: 70000
... A118: 940 | B118: 2025. 12. 07. 09:07:53 | C118: 김나경 | D118: 010-2618-0321 | E118: 671113 | F118: 2 | G118: 조은나 | H118: 010-7272-0082 | I118: 640925 | J118: =concatenate(C118,right(D118,4)) -> 김나경0321 | K118: =if(N118=0,"정상","중복") -> 정상 | L118: 70000 | M118: 70000 | N118: 0
A119: 282 | B119: 2025. 12. 07. 09:06:41 | C119: 김경애 | D119: 010-4532-4674 | E119: 661225 | F119: 1 | G119: - | H119: - | I119: - | J119: =concatenate(C119,right(D119,4)) -> 김경애4674 | K119: =if(N119=0,"정상","중복") -> 정상 | L119: 35000 | M119: 35000 | N119: 0
A120: 1192 | B120: 2025. 12. 07. 09:08:09 | C120: 박종구 | D120: 010-6221-2737 | E120: 660414 | F120: 2 | G120: 조성희 | H120: 010-6404-0942 | I120: 701110 | J120: =concatenate(C120,right(D120,4)) -> 박종구2737 | K120: =if(N120=0,"정상","중복") -> 정상 | L120: 70000 | M120: 70000 | N120: 0
A121: 436 | B121: 2025. 12. 07. 09:07:02 | C121: 라광수 | D121: 010-3352-1795 | E121: 690502 | F121: 2 | G121: 조미정 | H121: 010-5290-0071 | I121: 740429 | J121: =concatenate(C121,right(D121,4)) -> 라광수1795 | K121: =if(N121=0,"정상","중복") -> 정상 | L121: 70000 | M121: 70000 | N121: 0
A122: 582 | B122: 2025. 12. 07. 09:07:19 | C122: 정경희 | D122: 010-6543-3473 | E122: 630223 | F122: 2 | G122: 조규희 | H122: 010-9998-4952 | I122: 840116 | J122: =concatenate(C122,right(D122,4)) -> 정경희3473 | K122: =if(N122=0,"정상","중복") -> 정상 | L122: 70000 | M122: 70000 | N122: 0
A123: 415 | B123: 2025. 12. 07. 09:06:58 | C123: 송효석 | D123: 010-3206-2739 | E123: 550403 | F123: 2 | G123: 조규태 | H123: 010-8541-1708 | I123: 560418 | J123: =concatenate(C123,right(D123,4)) -> 송효석2739 | K123: =if(N123=0,"정상","중복") -> 정상 | L123: 70000 | M123: 70000 | N123: 0
A124: 960 | B124: 2025. 12. 07. 09:07:55 | C124: 김연심 | D124: 010-8661-9623 | E124: 801021 | F124: 2 | G124: 정희진 | H124: 010-7726-6932 | I124: 751226 | J124: =concatenate(C124,right(D124,4)) -> 김연심9623 | K124: =if(N124=0,"정상","중복") -> 정상 | L124: 70000 | M124: 70000 | N124: 0
A125: 556 | B125: 2025. 12. 07. 09:07:15 | C125: 김준환 | D125: 010-5489-4094 | E125: 551203 | F125: 2 | G125: 정주아 | H125: 010-8380-3278 | I125: 830213 | J125: =concatenate(C125,right(D125,4)) -> 김준환4094 | K125: =if(N125=0,"정상","중복") -> 정상 | L125: 70000 | M125: 70000 | N125: 0
A126: 387 | B126: 2025. 12. 07. 09:06:55 | C126: 장승희 | D126: 010-4084-5967 | E126: 750211 | F126: 2 | G126: 정종섭 | H126: 010-2374-3901 | I126: 451027 | J126: =concatenate(C126,right(D126,4)) -> 장승희5967 | K126: =if(N126=0,"정상","중복") -> 정상 | L126: 70000 | M126: 70000 | N126: 0
A127: 730 | B127: 2025. 12. 07. 09:07:34 | C127: 박옥자 | D127: 010-2250-4409 | E127: 620210 | F127: 2 | G127: 정정순 | H127: 010-9246-6577 | I127: 531004 | J127: =concatenate(C127,right(D127,4)) -> 박옥자4409 | K127: =if(N127=0,"정상","중복") -> 정상 | L127: 70000 | M127: 70000 | N127: 0
A128: 212 | B128: 2025. 12. 07. 09:06:15 | C128: 원지희 | D128: 010-9964-6017 | E128: 740805 | F128: 2 | G128: 정유진 | H128: 010-6270-2050 | I128: 760123 | J128: =concatenate(C128,right(D128,4)) -> 원지희6017 | K128: =if(N128=0,"정상","중복") -> 정상 | L128: 70000 | M128: 70000 | N128: 0
A129: 927 | B129: 2025. 12. 07. 09:07:52 | C129: 김은주 | D129: 010-7603-2133 | E129: 700401 | F129: 2 | G129: 정영실 | H129: 010-2880-9756 | I129: 710123 | J129: =concatenate(C129,right(D129,4)) -> 김은주2133 | K129: =if(N129=0,"정상","중복") -> 정상 | L129: 70000 | M129: 70000 | N129: 0
A130: 220 | B130: 2025. 12. 07. 09:06:21 | C130: 이진숙 | D130: 010-9744-9539 | E130: 580621 | F130: 2 | G130: 정영식 | H130: 010-7578-9538 | I130: 490529 | J130: =concatenate(C130,right(D130,4)) -> 이진숙9539 | K130: =if(N130=0,"정상","중복") -> 정상 | L130: 70000 | M130: 70000 | N130: 0
A131: 1079 | B131: 2025. 12. 07. 09:08:01 | C131: 이경자 | D131: 010-6332-4474 | E131: 750715 | F131: 2 | G131: 정영경 | H131: 010-7741-4479 | I131: 10628 | J131: =concatenate(C131,right(D131,4)) -> 이경자4474 | K131: =if(N131=0,"정상","중복") -> 정상 | L131: 70000 | M131: 70000 | N131: 0
... A419: 524 | B419: 2025. 12. 07. 09:07:10 | C419: 조찬영 | D419: 010-9172-2959 | E419: 801104 | F419: 2 | G419: 강선영 | H419: 010-9472-3342 | I419: 740104 | J419: =concatenate(C419,right(D419,4)) -> 조찬영2959 | K419: =if(N419=0,"정상","중복") -> 정상 | L419: 70000 | M419: 70000 | N419: 0
A420: 844 | B420: 2025. 12. 07. 09:07:46 | C420: 나현기 | D420: 010-4333-0612 | E420: 730712 | F420: 2 | G420: - | H420: - | I420: - | J420: =concatenate(C420,right(D420,4)) -> 나현기0612 | K420: =if(N420=0,"정상","중복") -> 정상 | L420: 70000 | M420: 70000 | N420: 0
A421: 1156 | B421: 2025. 12. 07. 09:08:06 | C421: 박정남 | D421: 010-5501-7595 | E421: 630716 | F421: 2 | G421: - | H421: - | I421: - | J421: =concatenate(C421,right(D421,4)) -> 박정남7595 | K421: =if(N421=0,"정상","중복") -> 정상 | L421: 70000 | M421: 70000 | N421: 0
A422: 1058 | B422: 2025. 12. 07. 09:08:00 | C422: 유미숙 | D422: 010-3710-0143 | E422: 660419 | F422: 2 | G422: - | H422: - | I422: - | J422: =concatenate(C422,right(D422,4)) -> 유미숙0143 | K422: =if(N422=0,"정상","중복") -> 정상 | L422: 70000 | M422: 70000 | N422: 0
A423: 249 | B423: 2025. 12. 07. 09:06:29 | C423: 이혜경 | D423: 010-6286-6721 | E423: 711021 | F423: 2 | G423: - | H423: - | I423: - | J423: =concatenate(C423,right(D423,4)) -> 이혜경6721 | K423: =if(N423=0,"정상","중복") -> 정상 | L423: 70000 | M423: 70000 | N423: 0
A424: 1244 | B424: 2025. 12. 07. 09:08:14 | C424: 이혜은 | D424: 010-9701-1016 | E424: 810415 | F424: 2 | G424: - | H424: - | I424: - | J424: =concatenate(C424,right(D424,4)) -> 이혜은1016 | K424: =if(N424=0,"정상","중복") -> 정상 | L424: 70000 | M424: 70000 | N424: 0
A425: 217 | B425: 2025. 12. 07. 09:06:16 | C425: 윤점례 | D425: 010-8127-0794 | E425: 570705 | F425: 1 | G425: - | H425: - | I425: - | J425: =concatenate(C425,right(D425,4)) -> 윤점례0794 | K425: =if(N425=0,"정상","중복") -> 정상 | L425: 35000 | M425: 35000 | N425: 0
A426: 991 | B426: 2025. 12. 07. 09:07:57 | C426: 신연희 | D426: 010-2205-0982 | E426: 641215 | F426: 1 | J426: =concatenate(C426,right(D426,4)) -> 신연희0982 | K426: =if(N426=0,"정상","중복") -> 중복 | L426: 35000 | M426: 70000 | N426: 35000
...

Sheet 1.신청입금매칭표
A1: 거래일시 | B1: 적요 | C1: 보낸분/받는분 | D1: 중복여부 | E1: 환불필요액 | F1: 송금메세지 원본 | G1: 입금액 | H1: 거래점 | I1: 문의여부 | J1: 문의수 | K1: 메모 | L1: 정상여부 | M1: 중복여부 | N1: 환불요청있는지 | O1: 취소여부 | P1: 환불확정 | Q1: 환불은행 | R1: 환불계좌 | S1: 예금주
A2: 2025.12.7 9:13 | B2: 스마트입금 | C2: 가재연6413 | D2: =vlookup(C2,'1. 신청자리스트'!J:N,2,false) -> 정상 | E2: =if(D2="정상","",vlookup(C2,'1. 신청자리스트'!J:N,6,false)) | F2: 가재연6413 | G2: 70000 | H2: 돈암동
A3: 2025.12.7 9:21 | B3: 전자금융 | C3: 강권종2013 | D3: =vlookup(C3,'1. 신청자리스트'!J:N,2,false) -> 정상 | F3: 강권종 2013 | G3: 35000 | H3: 우체국
A4: 2025.12.7 9:17 | B4: 전자금융 | C4: 강금옥4252 | D4: =vlookup(C4,'1. 신청자리스트'!J:N,2,false) -> 정상 | F4: 강금옥4252 | G4: 35000 | H4: 카뱅
A5: 2025.12.7 9:10 | B5: 전자금융 | C5: 강기정0940 | D5: =vlookup(C5,'1. 신청자리스트'!J:N,2,false) -> 정상 | F5: 강기정0940 | G5: 70000 | H5: 우리은행
A6: 2025.12.7 9:09 | B6: FBS입금 | C6: 강두연1222 | D6: =vlookup(C6,'1. 신청자리스트'!J:N,2,false) -> 정상 | F6: 강두연1222 | G6: 35000 | H6: 임베디
A7: 2025.12.7 9:11 | B7: 전자금융 | C7: 강미식9365 | D7: =vlookup(C7,'1. 신청자리스트'!J:N,2,false) -> 정상 | F7: 강미식9365 | G7: 70000 | H7: 하나은행
A8: 2025.12.7 9:11 | B8: 전자금융 | C8: 강민정0333 | D8: =vlookup(C8,'1. 신청자리스트'!J:N,2,false) -> 정상 | F8: 강민정0333 | G8: 35000 | H8: 카뱅
A9: 2025.12.7 9:10 | B9: 전자금융 | C9: 강성미3448 | D9: =vlookup(C9,'1. 신청자리스트'!J:N,2,false) -> 정상 | F9: ㄱㅏㅇㅅㅓㅇㅁㅣ34 | G9: 70000 | H9: 농협
A10: 2025.12.7 9:07 | B10: 스마트입금 | C10: 강윤진3620 | D10: =vlookup(C10,'1. 신청자리스트'!J:N,2,false) -> 정상 | F10: 강윤진3620 | G10: 35000 | H10: 상일역
A11: 2025.12.7 9:30 | B11: 전자금융 | C11: 강의정3696 | D11: =vlookup(C11,'1. 신청자리스트'!J:N,2,false) -> 정상 | F11: 강의정3696 | G11: 70000 | H11: 토스뱅크
A12: 2025.12.7 9:20 | B12: 전자금융 | C12: 강정아4860 | D12: =vlookup(C12,'1. 신청자리스트'!J:N,2,false) -> 정상 | F12: 강정아 4860 | G12: 70000 | H12: 우리은행
A13: 2025.12.7 9:16 | B13: 전자금융 | C13: 강종오8620 | D13: =vlookup(C13,'1. 신청자리스트'!J:N,2,false) -> 정상 | F13: 강종오8620 | G13: 70000 | H13: 하나은행 | I13: =VLOOKUP(C13, '문의'!D:E, 2, FALSE) -> #N/A | J13: 010-8228-8620 | K13: 정상진행 | L13: 강종오 660306 01082288620 강현수 960303 01087018620 | M13: X | N13: O | O13: O
A14: 2025.12.7 9:17 | B14: 전자금융 | C14: 강창숙5339 | D14: =vlookup(C14,'1. 신청자리스트'!J:N,2,false) -> 정상 | F14: 강창숙 | G14: 35000 | H14: 새마을금
A15: 2025.12.7 9:12 | B15: 전자금융 | C15: 강철민6334 | D15: =vlookup(C15,'1. 신청자리스트'!J:N,2,false) -> 정상 | F15: 강철민 | G15: 35000 | H15: 하나은행
A16: 2025.12.7 10:46 | B16: 전자금융 | C16: 강태준8305 | D16: =vlookup(C16,'1. 신청자리스트'!J:N,2,false) -> 정상 | F16: 강태준8305 | G16: 70000 | H16: 카뱅
A17: 2025.12.7 9:12 | B17: 전자금융 | C17: 강평애6138 | D17: =vlookup(C17,'1. 신청자리스트'!J:N,2,false) -> 정상 | F17: 강평애 | G17: 35000 | H17: 농협
A18: 2025.12.7 9:10 | B18: 전자금융 | C18: 강향숙1335 | D18: =vlookup(C18,'1. 신청자리스트'!J:N,2,false) -> 정상 | F18: 강향숙1335 | G18: 35000 | H18: 하나은행
A19: 2025.12.7 9:09 | B19: 전자금융 | C19: 강현수8943 | D19: =vlookup(C19,'1. 신청자리스트'!J:N,2,false) -> 정상 | F19: 강현수8943 | G19: 35000 | H19: 우리은행
A20: 2025.12.7 9:11 | B20: 스마트입금 | C20: 강현정2457 | D20: =vlookup(C20,'1. 신청자리스트'!J:N,2,false) -> 정상 | F20: 강현정 | G20: 70000 | H20: 동부산
A21: 2025.12.7 9:30 | B21: 전자금융 | C21: 강혜선4230 | D21: =vlookup(C21,'1. 신청자리스트'!J:N,2,false) -> 정상 | F21: 강혜선4230 | G21: 35000 | H21: 우체국
A22: 2025.12.7 16:36 | B22: 전자금융 | C22: 강회숙9464 | D22: =vlookup(C22,'1. 신청자리스트'!J:N,2,false) -> 정상 | F22: 강회숙 | G22: 35000 | H22: 농협
A23: 2025.12.7 22:25 | B23: 전자금융 | C23: 강효란2399 | D23: =vlookup(C23,'1. 신청자리스트'!J:N,2,false) -> 정상 | F23: 강효란2399 | G23: 35000 | H23: 토스뱅크
A24: 2025.12.7 9:11 | B24: 전자금융 | C24: 강효승2597 | D24: =vlookup(C24,'1. 신청자리스트'!J:N,2,false) -> 정상 | F24: 강효승 2597 | G24: 35000 | H24: 아이엠뱅
A25: 2025.12.7 9:20 | B25: 전자금융 | C25: 경현옥7399 | D25: =vlookup(C25,'1. 신청자리스트'!J:N,2,false) -> 정상 | F25: 경현옥 | G25: 70000 | H25: 우리은행 | I25: =VLOOKUP(C25, '문의'!D:E, 2, FALSE) -> [취소/환불] 신청내역을 찾을수 없다고 하네요 입금내역 캡쳐를 해났는데 찾을수 업다니 취소 신청합니다 계좌번호 12805572012001 입니다 우리은행 경현옥 | J25: {=INDEX('문의'!C:C, MATCH(C25, '문의'!D:D, 0))} -> 1041147399 | K25: 정상진행 | L25: 경현옥 680930 01041147399 박병은 680724 01037697399
A26: 2025.12.7 9:10 | B26: 스마트입금 | C26: 고경숙5566 | D26: =vlookup(C26,'1. 신청자리스트'!J:N,2,false) -> 정상 | F26: 고경숙5566 | G26: 35000 | H26: 영등구
A27: 2025.12.7 9:11 | B27: 전자금융 | C27: 고미영3605 | D27: =vlookup(C27,'1. 신청자리스트'!J:N,2,false) -> 정상 | F27: 고미영3605 | G27: 70000 | H27: 우리은행
A28: 2025.12.7 9:07 | B28: 전자금융 | C28: 고민경6970 | D28: =vlookup(C28,'1. 신청자리스트'!J:N,2,false) -> 정상 | F28: 고민경6970 | G28: 70000 | H28: 우리은행
A29: 2025.12.7 9:10 | B29: FBS입금 | C29: 고순화5385 | D29: =vlookup(C29,'1. 신청자리스트'!J:N,2,false) -> 정상 | F29: 고순화5385 | G29: 70000 | H29: 임베디
A30: 2025.12.7 9:38 | B30: 전자금융 | C30: 고은주7534 | D30: =vlookup(C30,'1. 신청자리스트'!J:N,2,false) -> 정상 | F30: 고은주7544 | G30: 35000 | H30: 농협
A31: 2025.12.7 9:10 | B31: 스마트입금 | C31: 고은혜7179 | D31: =vlookup(C31,'1. 신청자리스트'!J:N,2,false) -> 정상 | F31: 고은혜7179 | G31: 70000 | H31: 김해
A32: 2025.12.7 9:29 | B32: 전자금융 | C32: 고인숙9527 | D32: =vlookup(C32,'1. 신청자리스트'!J:N,2,false) -> 정상 | F32: 고인숙 9527 | G32: 70000 | H32: 하나은행
A33: 2025.12.7 9:17 | B33: 스마트입금 | C33: 공나윤5944 | D33: =vlookup(C33,'1. 신청자리스트'!J:N,2,false) -> 정상 | F33: 공나윤5944 | G33: 70000 | H33: 약수역 | I33: =VLOOKUP(C33, '문의'!D:E, 2, FALSE) -> [취소/환불] 신청된줄 알고 입금했습니다 나중에 확인하니 안된거네요ㅜ 환불계좌 국민 347 21 0261 158 금액 70,000 원 | J33: {=INDEX('문의'!C:C, MATCH(C33, '문의'!D:D, 0))} -> 1087205944 | K33: 정상진행 | L33: 공나윤 570108 01087205944 공연숙 530122 01087936200
A34: 2025.12.7 9:19 | B34: 스마트입금 | C34: 곽소영5074 | D34: =vlookup(C34,'1. 신청자리스트'!J:N,2,false) -> 정상 | F34: 곽소영5074 | G34: 35000 | H34: 길동
A35: 2025.12.7 9:11 | B35: 전자금융 | C35: 곽순영4559 | D35: =vlookup(C35,'1. 신청자리스트'!J:N,2,false) -> 정상 | F35: 곽순영(곽순영) | G35: 35000 | H35: 신한은행
A36: 2025.12.7 9:24 | B36: 전자금융 | C36: 구명숙1447 | D36: =vlookup(C36,'1. 신청자리스트'!J:N,2,false) -> 정상 | F36: 구명숙1447 | G36: 35000 | H36: 우리은행
A37: 2025.12.7 9:09 | B37: 전자금융 | C37: 구본순8367 | D37: =vlookup(C37,'1. 신청자리스트'!J:N,2,false) -> 정상 | F37: 구본순8367 | G37: 35000 | H37: 하나은행
A38: 2025.12.7 9:14 | B38: 전자금융 | C38: 권나희1900 | D38: =vlookup(C38,'1. 신청자리스트'!J:N,2,false) -> 정상 | F38: 권나희 | G38: 35000 | H38: 농협
A39: 2025.12.7 9:09 | B39: 스마트입금 | C39: 권미혜1965 | D39: =vlookup(C39,'1. 신청자리스트'!J:N,2,false) -> 정상 | F39: 권미혜1965 | G39: 70000 | H39: 동탄산
A40: 2025.12.7 9:14 | B40: 스마트입금 | C40: 권순모1100 | D40: =vlookup(C40,'1. 신청자리스트'!J:N,2,false) -> 정상 | F40: 권순모1100 | G40: 35000 | H40: 역삼동
...

Sheet 환불유령
A1: 거래일시 | B1: 적요 | C1: 보낸분/받는분 | D1: 송금메세지 원본 | E1: 입금액 | F1: 거래점 | G1: 전화번호 | H1: 메모 | I1: 환불확정 | J1: 환불은행 | K1: 환불계좌 | L1: 예금주
A2: 2025.12.7 9:13 | B2: FBS입금 | C2: 이경희3632 | D2: 이경희 | E2: 70000 | F2: 임베디 | G2: 1062843632 | H2: 환불신청 | I2: 70000 | J2: 신한은행 | K2: 110-182-225880 | L2: 이경희
A3: 2025.12.7 9:15 | B3: 전자금융 | C3: 김지원0505 | D3: 김지원 | E3: 70000 | F3: 토스뱅크 | G3: 1037660505 | H3: 환불신청 | I3: 70000 | J3: 대구은행 | K3: 139-08-002728 | L3: 김지원
A4: 2025.12.7 10:00 | B4: 전자금융 | C4: 최영신7030 | D4: 최영신7030 | E4: 70000 | F4: 농협 | G4: {=INDEX('문의'!C:C, MATCH(C4, '문의'!D:D, 0))} -> 1062497030 | H4: 환불신청 | I4: 70000 | J4: 농협은행 | K4: 82507252143737 | L4: 최영신
A5: 2025.12.7 9:11 | B5: 전자금융 | C5: 목진숙9465 | D5: 목진숙 | E5: 35000 | F5: 우리은행 | G5: 010-8907-9465 | H5: 환불신청 | I5: 35000 | J5: 우리은행 | K5: 29126620402001 | L5: 목진숙
A6: 2025.12.7 9:13 | B6: 전자금융 | C6: 하대호0480 | D6: 하대호0480 | E6: 70000 | F6: 중소기업 | G6: {=INDEX('문의'!C:C, MATCH(C6, '문의'!D:D, 0))} -> 1023650480 | H6: 환불신청 | I6: 70000 | J6: 우리은행 | K6: 1002143653378 | L6: 하대호
A7: 2025.12.7 9:11 | B7: 전자금융 | C7: 김경축4234 | D7: 깅경축4234 | E7: 70000 | F7: 농협 | G7: {=INDEX('문의'!C:C, MATCH(C7, '문의'!D:D, 0))} -> 1038884234 | H7: 환불신청 | I7: 70000 | J7: 농협은행 | K7: 20701352036741 | L7: 김경축
A8: 2025.12.7 9:22 | B8: 스마트입금 | C8: 안수진2502 | D8: =vlookup(C8,'1. 신청자리스트'!J:J,1,false) -> #N/A | E8: 70000 | F8: 동마산 | G8: {=INDEX('문의'!C:C, MATCH(C8, '문의'!D:D, 0))} -> 1041832502 | H8: 환불신청 | I8: 70000 | J8: 국민은행 | K8: 84400101571139 | L8: 안수진
A9: 2025.12.7 9:47 | B9: 전자금융 | C9: 김순아4577 | D9: 김순아 | E9: 35000 | F9: 신한은행 | G9: 1074504577 | H9: 환불신청 | I9: 35000 | J9: 신한은행 | K9: 110 341 754202 | L9: 김순아
A10: 2025.12.7 9:15 | B10: 스마트입금 | C10: 김종석2572 | D10: 김종석 | E10: 35000 | F10: 원주종 | G10: 010-4411-2572 | H10: 환불신청 | I10: 35000 | J10: 국민은행 | K10: 30380104099047 | L10: 김종석
A11: 2025.12.7 9:23 | B11: 전자금융 | C11: 양영주6549 | D11: 양영주6549 | E11: 35000 | F11: 우리은행 | G11: {=INDEX('문의'!C:C, MATCH(C11, '문의'!D:D, 0))} -> 1029786549 | H11: 환불신청 | I11: 35000 | J11: 우리은행 | K11: 1002-455-337917 | L11: 양영주
A12: 2025.12.7 9:34 | B12: 전자금융 | C12: 신귀순7188 | D12: 신귀순 | E12: 35000 | F12: 신한은행 | G12: {=INDEX('문의'!C:C, MATCH(C12, '문의'!D:D, 0))} -> 1086827188 | H12: 환불신청 | I12: 35000 | J12: 신한은행 | K12: 390-02-236862 | L12: 신귀순
A13: 2025.12.7 9:44 | B13: 전자금융 | C13: 이지영2400 | D13: 이지영2400 | E13: 70000 | F13: 농협 | G13: {=INDEX('문의'!C:C, MATCH(C13, '문의'!D:D, 0))} -> 1088912400 | H13: 환불신청 | I13: 70000 | J13: 농협 | K13: 351-0800-4754-63 | L13: 이지영
A14: 2025.12.7 9:08 | B14: 전자금융 | C14: 황우건1142 | D14: 황우건 | E14: 70000 | F14: 하나은행 | G14: {=INDEX('문의'!C:C, MATCH(C14, '문의'!D:D, 0))} -> 1077761142 | H14: 환불신청 | I14: 70000 | J14: 신한은행 | K14: 110-311-586382 | L14: 황우건
A15: 2025.12.7 9:08 | B15: 전자금융 | C15: 한훈6285 | D15: 한훈 | E15: 70000 | F15: 카뱅 | G15: {=INDEX('문의'!C:C, MATCH(C15, '문의'!D:D, 0))} -> 1038936285 | H15: 환불신청 | I15: 70000 | J15: 카카오뱅크 | K15: 3333038062377 | L15: 한훈
A16: 2025.12.7 9:13 | B16: 스마트입금 | C16: 이지현1846 | D16: 이지현 | E16: 60000 | F16: 상계역 | G16: {=INDEX('문의'!C:C, MATCH(C16, '문의'!D:D, 0))} -> 1037511846 | H16: 환불신청 | I16: 60000 | J16: KB국민은행 | K16: 353210016572 | L16: 이지현
A17: 2025.12.7 9:13 | B17: 전자금융 | C17: 조정희1020 | D17: 조정희 | E17: 35000 | F17: 하나은행 | G17: 010-8787-1020 | H17: 환불신청 | I17: 35000 | J17: 하나은행 | K17: 10989032816807 | L17: 조정희
A18: 2025.12.7 9:08 | B18: 전자금융 | C18: 홍수민7173 | D18: 홍수민 | E18: 35000 | F18: 농협 | G18: {=INDEX('문의'!C:C, MATCH(C18, '문의'!D:D, 0))} -> 1044027173 | H18: 환불신청 | I18: 35000 | J18: 농협은행 | K18: 3521665822603 | L18: 홍수민
A19: 2025.12.7 9:09 | B19: 인터넷입금이체 | C19: 김수진1210 | D19: 7940-0104- | E19: 35000 | F19: 방이역 | G19: 1053471210 | H19: 환불신청 | I19: 35000 | J19: 국민은행 | K19: 83630204225260 | L19: 김수진
A20: 2025.12.7 9:09 | B20: 전자금융 | C20: 이현진4548 | D20: 이현진 | E20: 35000 | F20: 토스뱅크 | G20: 1052864548 | H20: 환불신청 | I20: 35000 | J20: 국민은행 | K20: 34490104102263 | L20: 이현진
A21: 2025.12.7 9:10 | B21: 전자금융 | C21: 장현주0255 | D21: 장현주0255 | E21: 70000 | F21: 신한은행 | G21: {=INDEX('문의'!C:C, MATCH(C21, '문의'!D:D, 0))} -> 1099150255 | H21: 환불신청 | I21: 70000 | J21: 국민은행 | K21: 05321 0514 175 | L21: 장현주
A22: 2025.12.7 9:11 | B22: 전자금융 | C22: 김인숙6492 | D22: 김인숙6492 | E22: 70000 | F22: 우체국 | G22: {=INDEX('문의'!C:C, MATCH(C22, '문의'!D:D, 0))} -> 1089396492 | H22: 환불신청 | I22: 70000 | J22: 우체국 | K22: 1391202384007 | L22: 주영선
A23: 2025.12.7 9:11 | B23: 전자금융 | C23: 이형순8371 | D23: 이형순8371 | E23: 70000 | F23: 토스뱅크 | G23: {=INDEX('문의'!C:C, MATCH(C23, '문의'!D:D, 0))} -> 1089068371 | H23: 환불신청 | I23: 70000 | J23: 국민은행 | K23: 58540101426589 | L23: 이형순
A24: 2025.12.7 9:11 | B24: 전자금융 | C24: 장시아6446 | D24: 장시아 | E24: 70000 | F24: 중소기업 | G24: {=INDEX('문의'!C:C, MATCH(C24, '문의'!D:D, 0))} -> 1063976446 | H24: 환불신청 | I24: 70000 | J24: 기업은행 | K24: 20601857901052 | L24: 장시아
A25: 2025.12.7 9:12 | B25: 전자금융 | C25: 이금주6975 | D25: 이금주6975 | E25: 70000 | F25: 우리은행 | G25: 010-5326-6975 | H25: 환불신청 | I25: 70000 | J25: 신한은행 | K25: 55004451102 | L25: 이금주
A26: 2025.12.7 9:12 | B26: 전자금융 | C26: 조성식9450 | D26: 조성식9450 | E26: 35000 | F26: 우리은행 | G26: 010-6409-9450 | H26: 환불신청 | I26: 35000 | J26: 우리은행 | K26: 1002030414253 | L26: 조성식
A27: 2025.12.7 9:13 | B27: 전자금융 | C27: 김기선8430 | D27: 김기선8430 | E27: 35000 | F27: 카뱅 | G27: 010-9392-8430 | H27: 환불신청 | I27: 35000 | J27: 카카오뱅크 | K27: 3333287689323 | L27: 김기선
A28: 2025.12.7 9:15 | B28: 전자금융 | C28: 최윤지니엘5967 | D28: 최윤지니엘5967 | E28: 70000 | F28: 신한은행 | G28: 010-5485-5967 | H28: 환불신청 | I28: 70000 | J28: 신한은행 | K28: 110430843476 | L28: 장승희
A29: 2025.12.7 9:17 | B29: 전자금융 | C29: 서순임6148 | D29: 서순임 | E29: 35000 | F29: 농협 | G29: 010-7648-6148 | H29: 환불신청 | I29: 35000 | J29: 농협은행 | K29: 93712304335 | L29: 서순임
A30: 2025.12.7 9:21 | B30: 전자금융 | C30: 이현정1023 | D30: 이현정1023 | E30: 70000 | F30: 하나은행 | G30: {=INDEX('문의'!C:C, MATCH(C30, '문의'!D:D, 0))} -> 1046261023 | H30: 환불신청 | I30: 70000 | J30: 하나은행 | K30: 56291003492707 | L30: 이현정
A31: 2025.12.7 9:26 | B31: 스마트입금 | C31: 조은영6110 | D31: 조은영 | E31: 70000 | F31: 신정네 | G31: 010-2705-6110 | H31: 환불신청 | I31: 70000 | J31: 하나은행 | K31: 90491012445307 | L31: 조은영
A32: 2025.12.7 9:50 | B32: 전자금융 | C32: 함은순7393 | D32: 함은순7393 | E32: 140000 | F32: 아이엠뱅 | G32: {=INDEX('문의'!C:C, MATCH(C32, '문의'!D:D, 0))} -> 1066877393 | H32: 환불신청 | I32: 140000 | J32: im뱅크 | K32: 213 13 098764 | L32: 함은순
A33: 2025.12.7 9:10 | B33: 전자금융 | C33: 신세라2129 | D33: 신세라2129 | E33: 35000 | F33: 신한은행 | H33: 환불신청 | I33: 35000 | J33: 신한 | K33: 110 052 059479 | L33: 신세라
A34: 2025.12.7 9:13 | B34: 전자금융 | C34: 김호정4210 | D34: 김호정4210 | E34: 35000 | F34: 신한은행 | H34: 환불신청 | I34: 35000 | J34: 신한 | K34: 110434236960 | L34: 김호정
A35: 2025.12.7 9:15 | B35: 전자금융 | C35: 황정은5567 | D35: 황정은5567 | E35: 70000 | F35: 중소기업 | G35: 전화번호 찾을 수 없음 | I35: 70000
A36: 2025.12.7 9:39 | B36: 전자금융 | C36: 황희숙4316 | D36: 황희숙4316 | E36: 70000 | F36: 우체국 | G36: 전화번호 찾을 수 없음 | I36: 70000
A37: 2025.12.7 10:16 | B37: 전자금융 | C37: 이선자1675 | D37: 이선자1675 | E37: 35000 | F37: 농협 | G37: 전화번호 찾을 수 없음 | I37: 35000
A38: 2025.12.7 9:18 | B38: 오픈뱅킹입금 | C38: 김운자3029 | D38: 3029김운자 | E38: 35000 | F38: 농협 | G38: 전화번호 찾을 수 없음 | I38: 35000
A39: 2025.12.7 9:19 | B39: 전자금융 | C39: 김옥선2783 | D39: 김옥선 2783 | E39: 70000 | F39: 하나은행 | G39: 전화번호 찾을 수 없음 | I39: 70000
A40: 2025.12.7 9:09 | B40: FBS입금 | C40: 이지인 | D40: 이지인 | E40: 70000 | F40: 임베디 | G40: 전화번호 찾을 수 없음 | I40: 70000
...

Sheet 미입금
A1: ID | B1: 신청일시 | C1: 이름 | D1: 전화번호 | E1: 생년월일(앞자리) | F1: 티켓수 | G1: 동반자 이름 | H1: 동반자 전화번호 | I1: 동반자 생년월일 | J1: 입금상태 | K1: 임시인덱스 | L1: 취소여부 | M1: 입금여부 | N1: 입금수 | O1: 문의여부 | P1: 문의수
A2: 1246 | B2: 2025. 12. 07. 09:08:14 | C2: 이건로 | D2: 010-4461-9060 | E2: 911124 | F2: 2 | G2: - | H2: - | I2: - | J2: 대기 | K2: =concatenate(C2,right(D2,4)) -> 이건로9060 | L2: #N/A | M2: =if(vlookup(K2,'1.신청입금매칭표'!C:C,1,false)="","","정상") -> #N/A
A3: 1233 | B3: 2025. 12. 07. 09:08:13 | C3: 정선화 | D3: 010-4150-4541 | E3: 670922 | F3: 2 | G3: - | H3: - | I3: - | J3: 대기 | K3: =concatenate(C3,right(D3,4)) -> 정선화4541 | L3: #N/A | M3: =if(vlookup(K3,'1.신청입금매칭표'!C:C,1,false)="","","정상") -> #N/A
A4: 1240 | B4: 2025. 12. 07. 09:08:13 | C4: 최원현 | D4: 010-3000-5125 | E4: 630403 | F4: 2 | G4: - | H4: - | I4: - | J4: 대기 | K4: =concatenate(C4,right(D4,4)) -> 최원현5125 | L4: #N/A | M4: =if(vlookup(K4,'1.신청입금매칭표'!C:C,1,false)="","","정상") -> #N/A
A5: 1241 | B5: 2025. 12. 07. 09:08:13 | C5: 최영숙 | D5: 010-8507-0427 | E5: 580427 | F5: 2 | G5: - | H5: - | I5: - | J5: 대기 | K5: =concatenate(C5,right(D5,4)) -> 최영숙0427 | L5: #N/A | M5: =if(vlookup(K5,'1.신청입금매칭표'!C:C,1,false)="","","정상") -> #N/A
A6: 1208 | B6: 2025. 12. 07. 09:08:11 | C6: 문춘옥 | D6: 010-3698-3207 | E6: 540518 | F6: 2 | G6: - | H6: - | I6: - | J6: 대기 | K6: =concatenate(C6,right(D6,4)) -> 문춘옥3207 | L6: #N/A | M6: =if(vlookup(K6,'1.신청입금매칭표'!C:C,1,false)="","","정상") -> #N/A
A7: 1201 | B7: 2025. 12. 07. 09:08:10 | C7: 오지수 | D7: 010-4567-1444 | E7: 920202 | F7: 2 | G7: - | H7: - | I7: - | J7: 대기 | K7: =concatenate(C7,right(D7,4)) -> 오지수1444 | L7: #N/A | M7: =if(vlookup(K7,'1.신청입금매칭표'!C:C,1,false)="","","정상") -> #N/A
A8: 1173 | B8: 2025. 12. 07. 09:08:08 | C8: 채정희 | D8: 010-7173-9327 | E8: 801126 | F8: 1 | G8: - | H8: - | I8: - | J8: 대기 | K8: =concatenate(C8,right(D8,4)) -> 채정희9327 | L8: #N/A | M8: =if(vlookup(K8,'1.신청입금매칭표'!C:C,1,false)="","","정상") -> #N/A
A9: 1186 | B9: 2025. 12. 07. 09:08:08 | C9: 박계숙 | D9: 010-9834-5220 | E9: 550128 | F9: 1 | G9: - | H9: - | I9: - | J9: 대기 | K9: =concatenate(C9,right(D9,4)) -> 박계숙5220 | L9: #N/A | M9: =if(vlookup(K9,'1.신청입금매칭표'!C:C,1,false)="","","정상") -> #N/A
A10: 1167 | B10: 2025. 12. 07. 09:08:07 | C10: 이미화 | D10: 010-4117-7853 | E10: 691001 | F10: 1 | G10: - | H10: - | I10: - | J10: 대기 | K10: =concatenate(C10,right(D10,4)) -> 이미화7853 | L10: #N/A | M10: =if(vlookup(K10,'1.신청입금매칭표'!C:C,1,false)="","","정상") -> #N/A
A11: 1155 | B11: 2025. 12. 07. 09:08:06 | C11: 이종훈 | D11: 010-9019-9333 | E11: 600910 | F11: 1 | G11: - | H11: - | I11: - | J11: 대기 | K11: =concatenate(C11,right(D11,4)) -> 이종훈9333 | L11: #N/A | M11: =if(vlookup(K11,'1.신청입금매칭표'!C:C,1,false)="","","정상") -> #N/A
A12: 1136 | B12: 2025. 12. 07. 09:08:05 | C12: 이수향 | D12: 010-6773-2173 | E12: 730923 | F12: 1 | G12: - | H12: - | I12: - | J12: 대기 | K12: =concatenate(C12,right(D12,4)) -> 이수향2173 | L12: #N/A | M12: =if(vlookup(K12,'1.신청입금매칭표'!C:C,1,false)="","","정상") -> #N/A
A13: 1090 | B13: 2025. 12. 07. 09:08:02 | C13: 김현숙 | D13: 018-3634-7037 | E13: 701010 | F13: 1 | G13: - | H13: - | I13: - | J13: 대기 | K13: =concatenate(C13,right(D13,4)) -> 김현숙7037 | L13: #N/A | M13: =if(vlookup(K13,'1.신청입금매칭표'!C:C,1,false)="","","정상") -> #N/A
... A31: 848 | B31: 2025. 12. 07. 09:07:47 | C31: 전주영 | D31: 010-6648-7099 | E31: 670115 | F31: 1 | G31: - | H31: - | I31: - | J31: 대기 | K31: =concatenate(C31,right(D31,4)) -> 전주영7099 | L31: #N/A | M31: =if(vlookup(K31,'1.신청입금매칭표'!C:C,1,false)="","","정상") -> #N/A
A32: 853 | B32: 2025. 12. 07. 09:07:47 | C32: 정현미 | D32: 010-6425-4577 | E32: 710822 | F32: 2 | G32: 이상범 | H32: 010-6430-4577 | I32: 701102 | J32: 대기 | K32: =concatenate(C32,right(D32,4)) -> 정현미4577 | L32: #N/A | M32: =if(vlookup(K32,'1.신청입금매칭표'!C:C,1,false)="","","정상") -> #N/A
A33: 841 | B33: 2025. 12. 07. 09:07:46 | C33: 박주희 | D33: 010-3795-7056 | E33: 690128 | F33: 1 | G33: - | H33: - | I33: - | J33: 대기 | K33: =concatenate(C33,right(D33,4)) -> 박주희7056 | L33: #N/A | M33: =if(vlookup(K33,'1.신청입금매칭표'!C:C,1,false)="","","정상") -> #N/A
A34: 808 | B34: 2025. 12. 07. 09:07:43 | C34: 장경숙 | D34: 010-8622-9446 | E34: 640911 | F34: 1 | G34: - | H34: - | I34: - | J34: 대기 | K34: =concatenate(C34,right(D34,4)) -> 장경숙9446 | L34: #N/A | M34: =if(vlookup(K34,'1.신청입금매칭표'!C:C,1,false)="","","정상") -> #N/A
A35: 777 | B35: 2025. 12. 07. 09:07:40 | C35: 민선희 | D35: 010-2552-4580 | E35: 670726 | F35: 2 | G35: - | H35: - | I35: - | J35: 대기 | K35: =concatenate(C35,right(D35,4)) -> 민선희4580 | L35: #N/A | M35: =if(vlookup(K35,'1.신청입금매칭표'!C:C,1,false)="","","정상") -> #N/A
A36: 782 | B36: 2025. 12. 07. 09:07:40 | C36: 김현삼 | D36: 010-9315-4648 | E36: 711103 | F36: 2 | G36: - | H36: - | I36: - | J36: 대기 | K36: =concatenate(C36,right(D36,4)) -> 김현삼4648 | L36: #N/A | M36: =if(vlookup(K36,'1.신청입금매칭표'!C:C,1,false)="","","정상") -> #N/A
A37: 759 | B37: 2025. 12. 07. 09:07:39 | C37: 박판수 | D37: 010-3872-1238 | E37: 561228 | F37: 2 | G37: - | H37: - | I37: - | J37: 대기 | K37: =concatenate(C37,right(D37,4)) -> 박판수1238 | L37: #N/A | M37: =if(vlookup(K37,'1.신청입금매칭표'!C:C,1,false)="","","정상") -> #N/A
A38: 771 | B38: 2025. 12. 07. 09:07:39 | C38: 김윤자 | D38: 010-5040-3029 | E38: 610303 | F38: 1 | G38: - | H38: - | I38: - | J38: 대기 | K38: =concatenate(C38,right(D38,4)) -> 김윤자3029 | L38: #N/A | M38: =if(vlookup(K38,'1.신청입금매칭표'!C:C,1,false)="","","정상") -> #N/A
A39: 772 | B39: 2025. 12. 07. 09:07:39 | C39: 배강욱 | D39: 010-9351-7436 | E39: 670706 | F39: 2 | G39: - | H39: - | I39: - | J39: 대기 | K39: =concatenate(C39,right(D39,4)) -> 배강욱7436 | L39: #N/A | M39: =if(vlookup(K39,'1.신청입금매칭표'!C:C,1,false)="","","정상") -> #N/A
A40: 774 | B40: 2025. 12. 07. 09:07:39 | C40: 노점숙 | D40: 010-3339-3839 | E40: 581025 | F40: 1 | G40: - | H40: - | I40: - | J40: 대기 | K40: =concatenate(C40,right(D40,4)) -> 노점숙3839 | L40: #N/A | M40: =if(vlookup(K40,'1.신청입금매칭표'!C:C,1,false)="","","정상") -> #N/A
A41: 752 | B41: 2025. 12. 07. 09:07:38 | C41: 문애순 | D41: 010-6287-8514 | E41: 590913 | F41: 2 | G41: - | H41: - | I41: - | J41: 대기 | K41: =concatenate(C41,right(D41,4)) -> 문애순8514 | L41: #N/A | M41: =if(vlookup(K41,'1.신청입금매칭표'!C:C,1,false)="","","정상") -> #N/A
A42: 725 | B42: 2025. 12. 07. 09:07:34 | C42: 권신자 | D42: 010-8627-0356 | E42: 650905 | F42: 2 | G42: - | H42: - | I42: - | J42: 대기 | K42: =concatenate(C42,right(D42,4)) -> 권신자0356 | L42: #N/A | M42: =if(vlookup(K42,'1.신청입금매칭표'!C:C,1,false)="","","정상") -> #N/A
A43: 691 | B43: 2025. 12. 07. 09:07:31 | C43: 두의정 | D43: 010-8733-6133 | E43: 650723 | F43: 2 | G43: - | H43: - | I43: - | J43: 대기 | K43: =concatenate(C43,right(D43,4)) -> 두의정6133 | L43: #N/A | M43: =if(vlookup(K43,'1.신청입금매칭표'!C:C,1,false)="","","정상") -> #N/A
A44: 696 | B44: 2025. 12. 07. 09:07:31 | C44: 서염미 | D44: 010-8958-9500 | E44: 480405 | F44: 1 | G44: - | H44: - | I44: - | J44: 대기 | K44: =concatenate(C44,right(D44,4)) -> 서염미9500 | L44: #N/A | M44: =if(vlookup(K44,'1.신청입금매칭표'!C:C,1,false)="","","정상") -> #N/A
A45: 688 | B45: 2025. 12. 07. 09:07:30 | C45: 최인숙 | D45: 010-2387-6577 | E45: 611005 | F45: 1 | G45: - | H45: - | I45: - | J45: 대기 | K45: =concatenate(C45,right(D45,4)) -> 최인숙6577 | L45: #N/A | M45: =if(vlookup(K45,'1.신청입금매칭표'!C:C,1,false)="","","정상") -> #N/A
A46: 650 | B46: 2025. 12. 07. 09:07:27 | C46: 공춘자 | D46: 010-5338-7373 | E46: 550829 | F46: 2 | G46: 황송민 | H46: 010-8945-7600 | I46: 530515 | J46: 대기 | K46: =concatenate(C46,right(D46,4)) -> 공춘자7373 | L46: #N/A | M46: =if(vlookup(K46,'1.신청입금매칭표'!C:C,1,false)="","","정상") -> #N/A
A47: 635 | B47: 2025. 12. 07. 09:07:26 | C47: 장혜원 | D47: 010-7287-5338 | E47: 591006 | F47: 2 | G47: - | H47: - | I47: - | J47: 대기 | K47: =concatenate(C47,right(D47,4)) -> 장혜원5338 | L47: #N/A | M47: =if(vlookup(K47,'1.신청입금매칭표'!C:C,1,false)="","","정상") -> #N/A
A48: 636 | B48: 2025. 12. 07. 09:07:26 | C48: 박진희 | D48: 010-4779-2845 | E48: 730825 | F48: 1 | G48: - | H48: - | I48: - | J48: 대기 | K48: =concatenate(C48,right(D48,4)) -> 박진희2845 | L48: #N/A | M48: =if(vlookup(K48,'1.신청입금매칭표'!C:C,1,false)="","","정상") -> #N/A
A49: 641 | B49: 2025. 12. 07. 09:07:26 | C49: 유기순 | D49: 010-3062-1719 | E49: 610302 | F49: 1 | G49: - | H49: - | I49: - | J49: 대기 | K49: =concatenate(C49,right(D49,4)) -> 유기순1719 | L49: #N/A | M49: =if(vlookup(K49,'1.신청입금매칭표'!C:C,1,false)="","","정상") -> #N/A
A50: 642 | B50: 2025. 12. 07. 09:07:26 | C50: 오권자 | D50: 010-2370-1521 | E50: 610826 | F50: 1 | G50: - | H50: - | I50: - | J50: 대기 | K50: =concatenate(C50,right(D50,4)) -> 오권자1521 | L50: #N/A | M50: =if(vlookup(K50,'1.신청입금매칭표'!C:C,1,false)="","","정상") -> #N/A
A51: 644 | B51: 2025. 12. 07. 09:07:26 | C51: 임숙자 | D51: 010-4588-7481 | E51: 621212 | F51: 1 | G51: - | H51: - | I51: - | J51: 대기 | K51: =concatenate(C51,right(D51,4)) -> 임숙자7481 | L51: #N/A | M51: =if(vlookup(K51,'1.신청입금매칭표'!C:C,1,false)="","","정상") -> #N/A
A52: 647 | B52: 2025. 12. 07. 09:07:26 | C52: 노용헌 | D52: 010-5917-0238 | E52: 800913 | F52: 2 | G52: - | H52: - | I52: - | J52: 대기 | K52: =concatenate(C52,right(D52,4)) -> 노용헌0238 | L52: #N/A | M52: =if(vlookup(K52,'1.신청입금매칭표'!C:C,1,false)="","","정상") -> #N/A
A53: 617 | B53: 2025. 12. 07. 09:07:23 | C53: 허옥조 | D53: 010-9481-7063 | E53: 650801 | F53: 1 | G53: - | H53: - | I53: - | J53: 대기 | K53: =concatenate(C53,right(D53,4)) -> 허옥조7063 | L53: #N/A | M53: =if(vlookup(K53,'1.신청입금매칭표'!C:C,1,false)="","","정상") -> #N/A
A54: 603 | B54: 2025. 12. 07. 09:07:21 | C54: 김순화 | D54: 010-1211-0936 | E54: 620707 | F54: 2 | G54: - | H54: - | I54: - | J54: 대기 | K54: =concatenate(C54,right(D54,4)) -> 김순화0936 | L54: #N/A | M54: =if(vlookup(K54,'1.신청입금매칭표'!C:C,1,false)="","","정상") -> #N/A
A55: 606 | B55: 2025. 12. 07. 09:07:21 | C55: 조영민 | D55: 010-3781-5274 | E55: 550731 | F55: 1 | G55: - | H55: - | I55: - | J55: 대기 | K55: =concatenate(C55,right(D55,4)) -> 조영민5274 | L55: #N/A | M55: =if(vlookup(K55,'1.신청입금매칭표'!C:C,1,false)="","","정상") -> #N/A
A56: 591 | B56: 2025. 12. 07. 09:07:20 | C56: 안순옥 | D56: 010-6399-3025 | E56: 671013 | F56: 1 | G56: - | H56: - | I56: - | J56: 대기 | K56: =concatenate(C56,right(D56,4)) -> 안순옥3025 | L56: #N/A | M56: =if(vlookup(K56,'1.신청입금매칭표'!C:C,1,false)="","","정상") -> #N/A
A57: 589 | B57: 2025. 12. 07. 09:07:19 | C57: 안순희 | D57: 010-3450-2985 | E57: 610225 | F57: 1 | G57: - | H57: - | I57: - | J57: 대기 | K57: =concatenate(C57,right(D57,4)) -> 안순희2985 | L57: #N/A | M57: =if(vlookup(K57,'1.신청입금매칭표'!C:C,1,false)="","","정상") -> #N/A
...

Sheet 문의
A1: 번호 | B1: 이름 | C1: 전화번호 | E1: 문의내용 | F1: 문의일시 | G1: 답변상태 | H1: 답변내용 | I1: 답변일시
A2: 1 | B2: 이지현 | C2: 1037511846 | D2: =concatenate(B2,right(C2,4)) -> 이지현1846 | E2: [취소/환불] 잘못입금하여 취소환불 부탁드립니다 [환불정보] 금액: 60000원 은행: KB국민은행 계좌: 353210016572 예금주: 이지현 | F2: 46000.245 | G2: 미답변
A3: 2 | B3: 맹태만 | C3: 1037340296 | D3: =concatenate(B3,right(C3,4)) -> 맹태만0296 | E3: [입금/결제] 좌석번호 아직 확정이 안된건가요? | F3: 46000.189 | G3: 미답변
A4: 3 | B4: 김해영 | C4: 1065562831 | D4: =concatenate(B4,right(C4,4)) -> 김해영2831 | E4: [입금/결제] 신청내역 확인에서 비밀번호 오류라고 뜨고 중복입금 환불절차도 안 보입니다. 01065562831로 전화부탁드립니다. | F4: 46000.107 | G4: 미답변
A5: 4 | B5: 이상희 | C5: 1092993732 | D5: =concatenate(B5,right(C5,4)) -> 이상희3732 | E5: [기타문의] 일요일 아침 9시부터 대기했는데 뭔가 오류였는지 계속 들어가지지않다가 끝나버렸어요.혹시 반자리나시면 을려주실수있으실까요? 부탁드립니당.. | F5: 46000.067 | G5: 미답변
A6: 5 | B6: 손병기 | C6: 1062666306 | D6: =concatenate(B6,right(C6,4)) -> 손병기6306 | E6: [기타문의] 배우자 이혜경 전화번호 010-6286-6721 생년월일 711021 배우자는 입금했습니다. 저의 신청은 취소 되었지만 화면에는 계속신청화면이 나옵니다. 그래서 배우자 화면에선 제가 주신청자라고 동반자 등록이 안되고 있습니다. | F6: 46000.03 | G6: 미답변
A7: 6 | B7: 김혜성 | C7: 1072110988 | D7: =concatenate(B7,right(C7,4)) -> 김혜성0988 | E7: [취소/환불] 중복 입금으로 환불 신청합니다 [환불정보] 금액: 35000원 은행: 신한은행 계좌: 110040164025 예금주: 김혜성 | F7: 46000.021 | G7: 미답변
A8: 7 | B8: 이미연 | C8: 1055119963 | D8: =concatenate(B8,right(C8,4)) -> 이미연9963 | E8: [입금/결제] 안녕하세요. 제가 원래 티켓팅 날에 신청 폼까지 완료했다다 오류가 나서 안됐는데, 혹시나 하고 ‘신청확인’을 여러 번 하였으나 (마감 이후로도 수시로 확인함ㅠㅠ) 신청된 내역이 없는 것을 확인하였습니다. 그런데 방금 혹시나 하고 또 확인해보니 신청내역과 계좌번호도 보이고 입금대기중이라고 뜨는데 신청이 된걸까요?ㅠㅠ 공지에 입금기한이 8일까지라 방금 확인해 입금을 못했는데, 시스템상의 오류인지 궁금해서 문의드립니다. 갑자기 떴지만, 이미 8일이 지났기 때문에 입금해도 안되고 2차 티켓팅을 기다려야 하는 거겠죠?ㅠㅠ 바쁘실텐데 답변주시면 감사하겠습니다. | F8: 46000.02 | G8: 미답변
A9: 8 | B9: 손영숙 | C9: 1020145896 | D9: =concatenate(B9,right(C9,4)) -> 손영숙5896 | E9: [기타문의] 취소요청 했는데 죄송합니다만 다시 취소안하면 안되는지요 혹시 환불 아직 안됐으니 그냥 두시면 안될까요 | F9: 46000.012 | G9: 미답변
A10: 9 | B10: 최은혜 | C10: 1043332348 | D10: =concatenate(B10,right(C10,4)) -> 최은혜2348 | E10: [정보변경] 동반인을 김현영으로 신청했으나 동행인을 변경하였는데(어제문의) 변경신청이 김현영이 아닌 다른 이름이 변경이 안되면 전번과 주민번호 변경만으로도 입장이 가능한가요?? 입장시 동반인 이름을 신분증으로 확인하고 입장하는건지요?? | F10: 45999.995 | G10: 미답변
A11: 10 | B11: 주현경 | C11: 1089230225 | D11: =concatenate(B11,right(C11,4)) -> 주현경0225 | E11: [정보변경] 동반자 변경부탁드립니당 630214 010 - 8984 - 0214 | F11: 45999.975 | G11: 답변완료 | H11: 동반자 정보 변경했습니다. 신청내역 확인 화면에서 확인하시기 바랍니다. | I11: 45999.98
A12: 11 | B12: 차현주 | C12: 1045121480 | D12: =concatenate(B12,right(C12,4)) -> 차현주1480 | E12: [정보변경] 답변주신내용 확인 후 다시 문의드립니다. 직접 정보변경이 안되서요. 이름 : 하예진 생년월일, 910215 전화번호, 01057951480 정보변경에 이용해주시기 바랍니다 감사합니다^^ | F12: 45999.955 | G12: 답변완료 | H12: 하예진님 정보입력 했습니다. 차현주님 신청내역 확인 화면에서 자세한 내용 확인하시기 바랍니다. | I12: 45999.958
A13: 12 | B13: 하대호 | C13: 1023650480 | D13: =concatenate(B13,right(C13,4)) -> 하대호0480 | E13: [기타문의] 일요일 신청완료에 흥분한 나머지 입금자명 하대호로 한번 하대호0480으로 또 한번 이중으로 출금을 했는데 나중에 알고보니 저희 엄마도 신청에 성공을 하셨더라구요. 근데 동반자 정보수정을 오늘 6시까지라고 하던데 이미 하대호 이름으로 동반자 등록이 된지라 다른 신청 정보로 중복 등록이 안된다면서 현재 수정을 하지 못한 상황입니다. 하대호 예매신청건은 현재 예매는 다른 분들 위해서 취소 및 환불절차 진행중입니다. 차현주 01045121480 예매성공한 다른 가족입니다. 꼭 참여하고 싶은데 예매성공에 입금도 마쳤는데 이대로 어찌되는건지... 너무 궁금합니다... 아 그리고 한가지 건의드리고 싶습니다. 어르신들도 계시고 저같은 경우가 없을거라 생각지 않으니까요 단 하루 기간동안 정보수정을 하는건 너무 촉박한것 아닌가라는 생각이 들어서 조심스레 말씀드려봅니다! 위 문의 내용 확인후 꼭 답변부탁드립니다 제발요 감사합니다! 수고하십시요 꼭 21일 킨텍스서 됩고 싶습니다!! | F13: 45999.95 | G13: 답변완료 | H13: 차현주 신청 확인됩니다. 자세한 내용은 차현주 신청내역 확인 화면에서 확인하시기 바랍니다. | I13: 45999.956
A14: 13 | B14: 임순빈 | C14: 1050334525 | D14: =concatenate(B14,right(C14,4)) -> 임순빈4525 | E14: [취소/환불] 요청하신대로 작성했습니다. 입금시각은 12/7 09:28:58 입니다 [환불정보] 금액: 35000원 은행: SC제일은행 계좌: 10020221890 예금주: 임순빈 | F14: 45999.935 | G14: 답변완료 | H14: 확인했습니다. 다만, 환불 진행에 시간이 걸림을 양해 부탁드립니다. | I14: 45999.949
A15: 14 | B15: 김미 | C15: 1080220409 | D15: =concatenate(B15,right(C15,4)) -> 김미0409 | E15: [취소/환불] 죄송합니다. 남편이 같이 못가게 됐습니다. 한국 친구를 대신하는게 공정하지 않는거 같아서 그냥 1명을 취소합니다. 번거롭게해서 다시 한번 죄송합니다. 너무 좋아서 입가에 미소가 떠나질 않아요 ㅎㅎ 그리고 부탁드리고 싶은게 있는데요! 큐알코드가 제 폰으로 잘 안올거같아요! 한국폰이지만 일본이어서 문자 안올때가 많아요 ㅠㅠ 친구 휴대폰으로도 보내주시면 감사하겠습니다!! 01033012130(송희영) [환불정보] 금액: 35000원 은행: NH농협은행 계좌: 89512234855 예금주: 김미 | F15: 45999.886 | G15: 답변완료 | H15: 동반자 취소 하였습니다(2인신청 -> 1인신청) 환불 정보 확인하였습니다. 환불 처리에 시간이 걸림을 이해 부탁드립니다. QR 코드를 미리 보내지 않고 현장에서 확인할 예정입니다. 신분증과 핸드폰 지참 부탁드립니다. | I15: 45999.952
A16: 15 | B16: 박선화 | C16: 1081085598 | D16: =concatenate(B16,right(C16,4)) -> 박선화5598 | E16: [입금/결제] 박선화01081085598 12월7일 9시15분 입금완료 입금자명 박선화 | F16: 45999.884 | G16: 미답변
A17: 16 | B17: 한명실 | C17: 1090267644 | D17: =concatenate(B17,right(C17,4)) -> 한명실7644 | E17: [입금/결제] 중복 입금으로 계좌번호 남겨달라는 답변 받았습니다 기업(한명실) 377 030347 02 014 | F17: 45999.858 | G17: 답변완료 | H17: 확인했습니다. 다만 환불 처리에는 시간이 걸리는 점 양해 부탁드립니다. | I17: 45999.863
A18: 17 | B18: 한명실 | C18: 1090267644 | D18: =concatenate(B18,right(C18,4)) -> 한명실7644 | E18: [입금/결제] 입금은 바로 했는데 아직도 입금 대기.좌석대기로 뜨네요 입금은 됐는지 좌석은 배정된게 맞는지 답답하네요 더구나 2인 신청이라 같이 가실 분 스케줄 조정도 필요해서요 | F18: 45999.857 | G18: 답변완료 | H18: 현재 입금 확인중이라, 입금 대기로 나오는 것이 정상입니다. 입금 확인이 완료되면, 정보가 변경될 것입니다. 또한 좌석은 추후 배정될 것이니, 양해 부탁드립니다. | I18: 45999.939
A19: 18 | B19: 오효근 | C19: 1042276604 | D19: =concatenate(B19,right(C19,4)) -> 오효근6604 | E19: [정보변경] 대표 참여자 오효근 010 -4227-6604 ~ 동반자 정보 등록 전화번호 정정요청 신세라 010-9062-2126 이 아니고 010-9062-2129 으로 정정 요청드립니다(끝번호 9로 정정 요청) 고맙습니다 | F19: 45999.85 | G19: 답변완료 | H19: 정보 변경했습니다. 오효근님 신청내역 확인 화면에서 확인 부탁 드립니다. | I19: 45999.864
A20: 19 | B20: 권나희 | C20: 1088451900 | D20: =concatenate(B20,right(C20,4)) -> 권나희1900 | E20: [입금/결제] 1인 신청자입니다. 7일 신청햏는데 조회상 아직도 입금대기라고 뜨네요. 입금때 마음이 급해서 휴대폰 끝자리 1900을 쓰지 못해서 아직도 입금대기로 뜨는걸까요? 기다립니다. 권나희입니다 | F20: 45999.849 | G20: 답변완료 | H20: 현재 입금 확인중입니다. 추후 시스템에 반영이 완료되면 변동 예정입니다. 참고 부탁드립니다. | I20: 45999.865
A21: 20 | B21: 주현경 | C21: 1089230225 | D21: =concatenate(B21,right(C21,4)) -> 주현경0225 | E21: [정보변경] 동반자 변경하려고하는데 마감됏다고 나와요 어떻게하죠ㅠ | F21: 45999.845 | G21: 답변완료 | H21: 동반자 이름 변경은 원칙적으로 불가합니다. 전화번호/생년월일 변경만 가능합니다. 필요하시면, 문의 주시기 바랍니다. | I21: 45999.94
A22: 21 | B22: 김하나 | C22: 1063210794 | D22: =concatenate(B22,right(C22,4)) -> 김하나0794 | E22: [정보변경] 그럼 신청자 아니면 못가는건가요? 제가 큐알코드 받고 엄마가 대신 가는건 안되는건가요? | F22: 45999.812 | G22: 답변완료 | H22: 입장시 신분증과 입력된 정보가 일치해야 합니다. 앙해 부탁드립니다. | I22: 45999.828
A23: 22 | B23: 강경희 | C23: 1076573075 | D23: =concatenate(B23,right(C23,4)) -> 강경희3075 | E23: [취소/환불] 중복입긍환불신청합니다.대표신청인이 입금했는데 동반입장인이 중복입금한 상황입니다 [환불정보] 금액: 70000원 은행: 카카오뱅크 계좌: 3333218403973 예금주: 강경희 | F23: 45999.81 | G23: 답변완료 | H23: 현재 강경화님 동반 참석자 정보가 미입력 상태라, 중복 입금 확인이 어렵습니다. 우선 동반 참석자 정보를 입력하시고, 환불 요청을 다시 주시면 진행해 드리겠습니다. 강경화님 신청내역 확인 화면에서 동반 참석자 정보 입력 가능합니다(조치해 두었습니다) 진행하시고, 다시 문의주시면 감사하겠습니다. | I23: 45999.839
A24: 23 | B24: 이상열 | C24: 1026276052 | D24: =concatenate(B24,right(C24,4)) -> 이상열6052 | E24: [기타문의] 양도 여부 알려주세요!! 또 당일 가서 여기에 답변 받았는데 현장은 답변과 다르게 움직이고 이러면 안되니 공지 좀 하세요!! 충분히 나 올 예측 가능한 일 입니다.!! | F24: 45999.808 | G24: 답변완료 | H24: 양도는 불가합니다. 우려하시는 점 충분히 이해합니다. 참고하겠습니다. | I24: 45999.84
A25: 24 | B25: 김하나 | C25: 1063210794 | D25: =concatenate(B25,right(C25,4)) -> 김하나0794 | E25: [정보변경] 신청자 이름 변경해주시는 건가요?? 문의 드렸는데 답변이 없으시네요ㅜㅜ | F25: 45999.801 | G25: 답변완료 | H25: 원칙적으로 신청자 이름은 변경이 불가합니다. 양해 부탁드립니다. | I25: 45999.805
A26: 25 | B26: 김설자 | C26: 1091663415 | D26: =concatenate(B26,right(C26,4)) -> 김설자3415 | E26: [기타문의] 신청은 25.12.07 09:07분에 신청완료 했어요. 나이가 든 탓에 좌석배정이 늦어져 걱정됩니다. | F26: 45999.8 | G26: 미답변
A27: 26 | B27: 문채영 | C27: 1023590417 | D27: =concatenate(B27,right(C27,4)) -> 문채영0417 | E27: [입금/결제] 금일 11시 50분경 문채영0417 입금했습니다.. 아직 신청완료 상태가 되지않았는데.. 확인 부탁드립니다.. | F27: 45999.797 | G27: 답변완료 | H27: 현재 입금 확인중입니다. 추후 완료되면 신청내역 화면에서 확인 가능합니다. 참고 부탁드립니다. | I27: 45999.806
A28: 27 | B28: 김설자 | C28: 1091663415 | D28: =concatenate(B28,right(C28,4)) -> 김설자3415 | E28: [기타문의] 신청완료후 입금처리 되었는데요. 아직도 모두 대기로 떠있네요. | F28: 45999.797 | G28: 답변완료 | H28: 입금해주신 분들은 현재 입금 확인이 진행중이라, '입금대기'로 표시되는 것이 정상입니다. 입금데이터 확인 후 별도 공지 예정입니다 | I28: 45999.806
A29: 28 | B29: 나경희 | C29: 1065173088 | D29: =concatenate(B29,right(C29,4)) -> 나경희3088 | E29: [취소/환불] 어제 신청 접수 됐는 줄 알고 국민은행 윤석만 계좌로 입금 했는데 환불 부탁드립니다 [환불정보] 금액: 35000원 은행: 신한은행 계좌: 110213760202 예금주: 나경희 | F29: 45999.758 | G29: 답변완료 | H29: 확인했습니다. 다만 환불 처리에 시간이 걸리는 점 양해 부탁드립니다. | I29: 45999.808
A30: 29 | B30: 설다은 | C30: 1048925070 | D30: =concatenate(B30,right(C30,4)) -> 설다은5070 | E30: [기타문의] 2차모집도 열리나요? 만약 다시 열린다면 언제 가능한지 문의드립니다. | F30: 45999.744 | G30: 답변완료 | H30: 현재 확인중입니다. 혹, 2차 모집이 실시 되면 별도 공지할 예정입니다. | I30: 45999.747
A31: 30 | B31: 지은아 | C31: 1055313799 | D31: =concatenate(B31,right(C31,4)) -> 지은아3799 | E31: [취소/환불] 번거롭게 해드려서 죄송합니다 690830 지은아 [환불정보] 금액: 35000-60000원 은행: 카카오뱅크 계좌: 3333091258281 예금주: 지은아 | F31: 45999.743 | G31: 미답변
A32: 31 | B32: 김정화 | C32: 1094956109 | D32: =concatenate(B32,right(C32,4)) -> 김정화6109 | E32: [정보변경] 김정화 01094956109 이경하 01021236109(동반자) 신청확인시 동반자이름과 전번 쓸 시간이없었습니다. | F32: 45999.728 | G32: 미답변
A33: 32 | B33: 나경희 | C33: 1065173088 | D33: =concatenate(B33,right(C33,4)) -> 나경희3088 | E33: [취소/환불] 안녕하세요 신청이 되었다고 떠서 입금했는데 오류였나보네요 환불부탁드려요 [환불정보] 금액: 35000원 은행: 신한은행 계좌: 110213760202 예금주: 나경희 | F33: 45999.728 | G33: 답변완료 | H33: 확인했습니다. 다만 환불 처리에 시간이 걸린다는 점 미리 말씀드립니다. 양해 부탁드립니다. | I33: 45999.744
A34: 33 | B34: 안은숙 | C34: 1028045404 | D34: =concatenate(B34,right(C34,4)) -> 안은숙5404 | E34: [취소/환불] 중복입금 환불창이 활성화 되지 않습니다 ( 3회 입금해서 2회 환불 받아야 하는데, 1회 환불 처리 중이라 그런듯 합니다) 09 :11 안은숙 5404 환불해 주세요 계좌번호는 다음과 같습니다 기업은행 335 002855 03 018 안은숙 입니다 | F34: 45999.725 | G34: 답변완료 | H34: 확인했습니다. 다만 환불 처리에 시간이 걸리는 점 양해 부탁드립니다. | I34: 45999.746
A35: 34 | B35: 나경희 | C35: 1065173088 | D35: =concatenate(B35,right(C35,4)) -> 나경희3088 | E35: [입금/결제] 어제 신청접수 된 줄 알고 3시32분27초에 국민은행 윤석만 계좌로 35000원 입금 했는데 환불 받을려면 어떻게 해야 하나요? 아직 답변이 없어 다시 보냅니다 | F35: 45999.724 | G35: 미답변
A36: 35 | B36: 박서윤 | C36: 1050399373 | D36: =concatenate(B36,right(C36,4)) -> 박서윤9373 | E36: [정보변경] 안녕하세요. 처음 안내에서 동반인 바꿀수 있다 해서. 동반인 바꾸려나 이름 바꿀수 없다하고. 주민 번호와 전번만 바꿀수 있다는 안내가 있는데. 그럼 동인 이름과 주민번호 대조 후 일치 해야 하나요? 아니면 동반인 이름은 못 바꾸니 그냥 두고 전번과 주민 번호만으로 입장 가능한가요? | F36: 45999.723 | G36: 답변완료 | H36: 입장시 신분증과 입력 정보가 동일해야 합니다. 참고 부탁드립니다. | I36: 45999.753
A37: 36 | B37: 서동미 | C37: 1032596212 | D37: =concatenate(B37,right(C37,4)) -> 서동미6212 | E37: [기타문의] 왜 계속 입금대기라고 뜰까요? | F37: 45999.722 | G37: 답변완료 | H37: 입금해주신 분들은 현재 입금 확인이 진행중이라, '입금대기'로 표시되는 것이 정상입니다. 입금데이터 확인 후 별도 공지 예정입니다 | I37: 45999.811
A38: 37 | B38: 김정화 | C38: 1094956109 | D38: =concatenate(B38,right(C38,4)) -> 김정화6109 | E38: [입금/결제] 신청확인후 입금완료했는데 신청내역 확인불가입니다. 오늘8일(18:00) 까지 문의하라고 공지ㅜ보고 연락합니다. 김정화, 01094956109 하나은행(김정화) 입금시점9:45 | F38: 45999.718 | G38: 미답변
A39: 38 | B39: 김나영 | C39: 1052325712 | D39: =concatenate(B39,right(C39,4)) -> 김나영5712 | E39: [입금/결제] 2인티켓 신청해서 7만원을 입금해야하는데 3만5천원씩 입금해서 입금확인시 확인부탁드립니다. 김나영 5712 09:15:45 김옥선 5943 09:18:26 따로 입금함. 중복아니고..환불 받을건없습니다 혹시라도 잘못될까봐 걱정이라서요ㅜ | F39: 45999.715 | G39: 답변완료 | H39: 확인했습니다. | I39: 45999.755
A40: 39 | B40: 문현주 | C40: 1063165693 | D40: =concatenate(B40,right(C40,4)) -> 문현주5693 | E40: [기타문의] 동반자 등록하려고 하는데 주신청자라서 등록이 안된다고 하는데 어떻게 해야 하나요 함정순 620819입니다 | F40: 45999.714 | G40: 답변완료 | H40: 대표 신청자 문현주님에게 한정순님을 동반 참석자로 등록했습니다. 신청 내역 확인에서 확인 부탁드립니다. | I40: 45999.783
...

Sheet 취소환불신청자
A1: ID | B1: 신청일시 | C1: 이름 | D1: 전화번호 | F1: 생년월일(앞자리) | G1: 티켓수 | H1: 동반자 이름 | I1: 동반자 전화번호 | J1: 상태 | K1: 취소일시 | L1: 취소사유 | M1: 환불상태 | N1: 환불금액 | O1: 환불은행 | P1: 환불계좌 | Q1: 예금주
A2: 1182 | B2: 2025. 12. 07. 09:08:08 | C2: 손영숙 | D2: 010-2014-5896 | E2: =concatenate(C2,right(D2,4)) -> 손영숙5896 | F2: 620515 | G2: 1 | H2: - | I2: - | J2: 삭제됨 | K2: 2025. 12. 08. 23:16:02 | L2: - | M2: - | N2: - | O2: - | P2: - | Q2: -
A3: 1009 | B3: 2025. 12. 07. 09:07:58 | C3: 진라희 | D3: 010-7597-3388 | E3: =concatenate(C3,right(D3,4)) -> 진라희3388 | F3: 691026 | G3: 2 | H3: 이현정 | I3: 010-4626-1023 | J3: 삭제됨 | K3: 2025. 12. 07. 21:17:26 | L3: 본인 취소 요청 | M3: - | N3: - | O3: - | P3: - | Q3: -
A4: 898 | B4: 2025. 12. 07. 09:07:51 | C4: 배우식 | D4: 010-2377-2555 | E4: =concatenate(C4,right(D4,4)) -> 배우식2555 | F4: 550602 | G4: 2 | H4: - | I4: - | J4: 삭제됨 | K4: 2025. 12. 07. 21:02:46 | L4: 본인 취소 요청 | M4: - | N4: - | O4: - | P4: - | Q4: -
A5: 799 | B5: 2025. 12. 07. 09:07:42 | C5: 정두식 | D5: 010-6201-1414 | E5: =concatenate(C5,right(D5,4)) -> 정두식1414 | F5: 620923 | G5: 2 | H5: - | I5: - | J5: 삭제됨 | K5: 2025. 12. 07. 20:42:22 | L5: 본인 취소 요청 | M5: - | N5: - | O5: - | P5: - | Q5: -
A6: 360 | B6: 2025. 12. 07. 09:06:53 | C6: 김정숙 | D6: 010-2391-6517 | E6: =concatenate(C6,right(D6,4)) -> 김정숙6517 | F6: 580415 | G6: 2 | H6: - | I6: - | J6: 삭제됨 | K6: 2025. 12. 07. 20:33:43 | L6: 본인 취소 요청 | M6: - | N6: - | O6: - | P6: - | Q6: -
A7: 327 | B7: 2025. 12. 07. 09:06:50 | C7: 이유주 | D7: 010-7138-0037 | E7: =concatenate(C7,right(D7,4)) -> 이유주0037 | F7: 640228 | G7: 2 | H7: - | I7: - | J7: 삭제됨 | K7: 2025. 12. 08. 19:40:58 | L7: - | M7: - | N7: - | O7: - | P7: - | Q7: -
A8: 319 | B8: 2025. 12. 07. 09:06:49 | C8: 함정순 | D8: 010-8885-5693 | E8: =concatenate(C8,right(D8,4)) -> 함정순5693 | F8: 620819 | G8: 2 | H8: - | I8: - | J8: 삭제됨 | K8: 2025. 12. 07. 21:05:05 | L8: 본인 취소 요청 | M8: - | N8: - | O8: - | P8: - | Q8: -
A9: 298 | B9: 2025. 12. 07. 09:06:45 | C9: 서우주 | D9: 010-4023-4943 | E9: =concatenate(C9,right(D9,4)) -> 서우주4943 | F9: 90804 | G9: 2 | H9: - | I9: - | J9: 삭제됨 | K9: 2025. 12. 07. 20:53:07 | L9: 본인 취소 요청 | M9: - | N9: - | O9: - | P9: - | Q9: -
A10: 170 | B10: 2025. 12. 07. 09:06:04 | C10: 하대호 | D10: 010-2365-0480 | E10: =concatenate(C10,right(D10,4)) -> 하대호0480 | F10: 930114 | G10: 2 | H10: 하예진 | I10: 010-5795-1480 | J10: 삭제됨 | K10: 2025. 12. 07. 21:39:35 | L10: 본인 취소 요청 | M10: pending | N10: 70,000원 | O10: 우리은행 | P10: 1002143653378 | Q10: 하대호
A11: 1229 | B11: 2025. 12. 07. 09:08:13 | C11: 백승옥 | D11: 010-3745-9494 | E11: =concatenate(C11,right(D11,4)) -> 백승옥9494 | F11: 640508 | G11: 1 | H11: - | I11: - | J11: 취소됨 | K11: 2025. 12. 08. 09:22:25 | L11: 본인 취소 요청 | M11: - | N11: - | O11: - | P11: - | Q11: -
A12: 1163 | B12: 2025. 12. 07. 09:08:07 | C12: 서순임 | D12: 010-7648-6148 | E12: =concatenate(C12,right(D12,4)) -> 서순임6148 | F12: 661113 | G12: 1 | H12: - | I12: - | J12: 취소됨 | K12: 2025. 12. 08. 13:29:31 | L12: 본인 취소 요청 | M12: pending | N12: 35,000원 | O12: 농협은행 | P12: 93712304335 | Q12: 서순임
A13: 1165 | B13: 2025. 12. 07. 09:08:07 | C13: 이현정 | D13: 010-4626-1023 | E13: =concatenate(C13,right(D13,4)) -> 이현정1023 | F13: 741023 | G13: 2 | H13: 남궁영희 | I13: 010-3710-5782 | J13: 취소됨 | K13: 2025. 12. 07. 21:10:46 | L13: 본인 취소 요청 | M13: pending | N13: 70,000원 | O13: 하나은행 | P13: 56291003492707 | Q13: 이현정
A14: 1137 | B14: 2025. 12. 07. 09:08:05 | C14: 김종석 | D14: 010-4411-2572 | E14: =concatenate(C14,right(D14,4)) -> 김종석2572 | F14: 550321 | G14: 1 | H14: - | I14: - | J14: 취소됨 | K14: 2025. 12. 07. 22:03:18 | L14: 본인 취소 요청 | M14: pending | N14: 35,000원 | O14: 국민은행 | P14: 30380104099047 | Q14: 김종석
A15: 1127 | B15: 2025. 12. 07. 09:08:04 | C15: 이권옥 | D15: 010-7637-6330 | E15: =concatenate(C15,right(D15,4)) -> 이권옥6330 | F15: 721118 | G15: 1 | H15: - | I15: - | J15: 취소됨 | K15: 2025. 12. 08. 12:35:57 | L15: 본인 취소 요청 | M15: - | N15: - | O15: - | P15: - | Q15: -
A16: 1026 | B16: 2025. 12. 07. 09:07:59 | C16: 최영신 | D16: 010-6249-7030 | E16: =concatenate(C16,right(D16,4)) -> 최영신7030 | F16: 740310 | G16: 1 | H16: - | I16: - | J16: 취소됨 | K16: 2025. 12. 09. 01:40:36 | L16: 본인 취소 요청 | M16: pending | N16: 70,000원 | O16: 농협은행 | P16: 82507252143737 | Q16: 최영신
A17: 1030 | B17: 2025. 12. 07. 09:07:59 | C17: 함은순 | D17: 010-6687-7393 | E17: =concatenate(C17,right(D17,4)) -> 함은순7393 | F17: 700527 | G17: 2 | H17: 함은순 | I17: 010-6204-7393 | J17: 취소됨 | K17: 2025. 12. 07. 20:17:38 | L17: 본인 취소 요청 | M17: pending | N17: 140,000원 | O17: 대구은행 | P17: 21313098764 | Q17: 서진수
A18: 1034 | B18: 2025. 12. 07. 09:07:59 | C18: 조성식 | D18: 010-6409-9450 | E18: =concatenate(C18,right(D18,4)) -> 조성식9450 | F18: 630724 | G18: 1 | H18: - | I18: - | J18: 취소됨 | K18: 2025. 12. 08. 08:18:17 | L18: 본인 취소 요청 | M18: pending | N18: 35,000원 | O18: 우리은행 | P18: 1002030414253 | Q18: 조성식
A19: 991 | B19: 2025. 12. 07. 09:07:57 | C19: 신연희 | D19: 010-2205-0982 | E19: =concatenate(C19,right(D19,4)) -> 신연희0982 | F19: 641215 | G19: 1 | H19: - | I19: - | J19: 취소됨 | K19: 2025. 12. 08. 23:14:27 | L19: 본인 취소 요청 | M19: pending | N19: 35,000원 | O19: 신한은행 | P19: 36506330677 | Q19: 신연희
A20: 944 | B20: 2025. 12. 07. 09:07:54 | C20: 손미화 | D20: 010-8785-8192 | E20: =concatenate(C20,right(D20,4)) -> 손미화8192 | F20: 590930 | G20: 1 | H20: - | I20: - | J20: 취소됨 | K20: 2025. 12. 07. 20:50:18 | L20: 본인 취소 요청 | M20: - | N20: - | O20: - | P20: - | Q20: -
A21: 918 | B21: 2025. 12. 07. 09:07:52 | C21: 최원현 | D21: 010-3000-5775 | E21: =concatenate(C21,right(D21,4)) -> 최원현5775 | F21: 600729 | G21: 2 | H21: - | I21: - | J21: 취소됨 | K21: 2025. 12. 07. 20:59:04 | L21: 본인 취소 요청 | M21: pending | N21: 35,000원 | O21: 신한은행 | P21: 110478781303 | Q21: 최원현
A22: 930 | B22: 2025. 12. 07. 09:07:52 | C22: 손병기 | D22: 010-6266-6306 | E22: =concatenate(C22,right(D22,4)) -> 손병기6306 | F22: 681011 | G22: 2 | H22: - | I22: - | J22: 취소됨 | K22: 2025. 12. 07. 20:02:06 | L22: 본인 취소 요청 | M22: - | N22: - | O22: - | P22: - | Q22: -
A23: 904 | B23: 2025. 12. 07. 09:07:51 | C23: 김정우 | D23: 010-3004-7510 | E23: =concatenate(C23,right(D23,4)) -> 김정우7510 | F23: 960123 | G23: 2 | H23: - | I23: - | J23: 취소됨 | K23: 2025. 12. 08. 12:40:45 | L23: 본인 취소 요청 | M23: - | N23: - | O23: - | P23: - | Q23: -
A24: 892 | B24: 2025. 12. 07. 09:07:50 | C24: 장현주 | D24: 010-9915-0255 | E24: =concatenate(C24,right(D24,4)) -> 장현주0255 | F24: 680716 | G24: 2 | H24: 조현곤 | I24: 010-8352-9344 | J24: 취소됨 | K24: 2025. 12. 07. 19:51:27 | L24: 본인 취소 요청 | M24: pending | N24: 70,000원 | O24: KB국민은행 | P24: 53210514175 | Q24: 장현주
A25: 825 | B25: 2025. 12. 07. 09:07:45 | C25: 최윤지니엘 | D25: 010-5485-5967 | E25: =concatenate(C25,right(D25,4)) -> 최윤지니엘5967 | F25: 50127 | G25: 2 | H25: 최승필 | I25: 010-3067-5967 | J25: 취소됨 | K25: 2025. 12. 08. 13:08:20 | L25: 본인 취소 요청 | M25: pending | N25: 70,000원 | O25: 신한은행 | P25: 110430843476 | Q25: 장승희
A26: 818 | B26: 2025. 12. 07. 09:07:44 | C26: 김기선 | D26: 010-9392-8430 | E26: =concatenate(C26,right(D26,4)) -> 김기선8430 | F26: 601116 | G26: 1 | H26: - | I26: - | J26: 취소됨 | K26: 2025. 12. 08. 15:07:49 | L26: 본인 취소 요청 | M26: pending | N26: 35,000원 | O26: 카카오뱅크 | P26: 3333287689323 | Q26: 김기선
A27: 800 | B27: 2025. 12. 07. 09:07:42 | C27: 민충식 | D27: 010-4194-1645 | E27: =concatenate(C27,right(D27,4)) -> 민충식1645 | F27: 820710 | G27: 2 | H27: - | I27: - | J27: 취소됨 | K27: 2025. 12. 07. 22:15:14 | L27: 본인 취소 요청 | M27: - | N27: - | O27: - | P27: - | Q27: -
A28: 801 | B28: 2025. 12. 07. 09:07:42 | C28: 황연자 | D28: 010-4548-7927 | E28: =concatenate(C28,right(D28,4)) -> 황연자7927 | F28: 680103 | G28: 1 | H28: - | I28: - | J28: 취소됨 | K28: 2025. 12. 08. 09:30:05 | L28: 본인 취소 요청 | M28: pending | N28: 35,000원 | O28: 농협은행 | P28: 3564548792773 | Q28: 황연자
A29: 780 | B29: 2025. 12. 07. 09:07:40 | C29: 조문경 | D29: 010-8961-2671 | E29: =concatenate(C29,right(D29,4)) -> 조문경2671 | F29: 710901 | G29: 1 | H29: - | I29: - | J29: 취소됨 | K29: 2025. 12. 08. 15:17:09 | L29: 본인 취소 요청 | M29: - | N29: - | O29: - | P29: - | Q29: -
A30: 763 | B30: 2025. 12. 07. 09:07:39 | C30: 박은희 | D30: 010-2896-3573 | E30: =concatenate(C30,right(D30,4)) -> 박은희3573 | F30: 660411 | G30: 1 | H30: - | I30: - | J30: 취소됨 | K30: 2025. 12. 07. 21:27:40 | L30: 본인 취소 요청 | M30: - | N30: - | O30: - | P30: - | Q30: -
A31: 775 | B31: 2025. 12. 07. 09:07:39 | C31: 김재웅 | D31: 010-2205-9494 | E31: =concatenate(C31,right(D31,4)) -> 김재웅9494 | F31: 630601 | G31: 1 | H31: - | I31: - | J31: 취소됨 | K31: 2025. 12. 08. 09:23:14 | L31: 본인 취소 요청 | M31: - | N31: - | O31: - | P31: - | Q31: -
A32: 755 | B32: 2025. 12. 07. 09:07:38 | C32: 조은영 | D32: 010-2705-6110 | E32: =concatenate(C32,right(D32,4)) -> 조은영6110 | F32: 640815 | G32: 2 | H32: 김기제르모 | I32: 010-3339-1417 | J32: 취소됨 | K32: 2025. 12. 08. 06:40:24 | L32: 본인 취소 요청 | M32: pending | N32: 70,000원 | O32: 하나은행 | P32: 90491012445307 | Q32: 조은영
A33: 713 | B33: 2025. 12. 07. 09:07:33 | C33: 박규현 | D33: 010-2906-5383 | E33: =concatenate(C33,right(D33,4)) -> 박규현5383 | F33: 751027 | G33: 1 | H33: - | I33: - | J33: 취소됨 | K33: 2025. 12. 08. 18:56:02 | L33: 본인 취소 요청 | M33: - | N33: - | O33: - | P33: - | Q33: -
A34: 715 | B34: 2025. 12. 07. 09:07:33 | C34: 김동현 | D34: 010-3130-2954 | E34: =concatenate(C34,right(D34,4)) -> 김동현2954 | F34: 720308 | G34: 2 | H34: - | I34: - | J34: 취소됨 | K34: 2025. 12. 07. 23:14:01 | L34: 본인 취소 요청 | M34: - | N34: - | O34: - | P34: - | Q34: -
A35: 717 | B35: 2025. 12. 07. 09:07:33 | C35: 목진숙 | D35: 010-8907-9465 | E35: =concatenate(C35,right(D35,4)) -> 목진숙9465 | F35: 661114 | G35: 1 | H35: - | I35: - | J35: 취소됨 | K35: 2025. 12. 08. 15:03:25 | L35: 본인 취소 요청 | M35: pending | N35: 35,000원 | O35: 우리은행 | P35: 29126620402001 | Q35: 목진숙
A36: 685 | B36: 2025. 12. 07. 09:07:30 | C36: 김경축 | D36: 010-3888-4234 | E36: =concatenate(C36,right(D36,4)) -> 김경축4234 | F36: 490201 | G36: 2 | H36: - | I36: - | J36: 취소됨 | K36: 2025. 12. 07. 20:17:43 | L36: 본인 취소 요청 | M36: pending | N36: 70,000원 | O36: 농협은행 | P36: 20701352036741 | Q36: 김경축
A37: 648 | B37: 2025. 12. 07. 09:07:27 | C37: 차성애 | D37: 010-3994-2464 | E37: =concatenate(C37,right(D37,4)) -> 차성애2464 | F37: 640725 | G37: 1 | H37: - | I37: - | J37: 취소됨 | K37: 2025. 12. 07. 21:04:50 | L37: 본인 취소 요청 | M37: - | N37: - | O37: - | P37: - | Q37: -
A38: 656 | B38: 2025. 12. 07. 09:07:27 | C38: 이형순 | D38: 010-8906-8371 | E38: =concatenate(C38,right(D38,4)) -> 이형순8371 | F38: 611214 | G38: 2 | H38: 고세준 | I38: 010-7188-3304 | J38: 취소됨 | K38: 2025. 12. 08. 15:36:00 | L38: 본인 취소 요청 | M38: pending | N38: 70,000원 | O38: 국민은행 | P38: 58540101426589 | Q38: 이형순
A39: 592 | B39: 2025. 12. 07. 09:07:20 | C39: 강종오 | D39: 010-8228-8620 | E39: =concatenate(C39,right(D39,4)) -> 강종오8620 | F39: 660306 | G39: 2 | H39: 김성미 | I39: 010-7430-4447 | J39: 취소됨 | K39: 2025. 12. 08. 17:58:48 | L39: 본인 취소 요청 | M39: pending | N39: 70,000원 | O39: 농협은행 | P39: 23713456188855 | Q39: 강종오
A40: 578 | B40: 2025. 12. 07. 09:07:18 | C40: 장시아 | D40: 010-6397-6446 | E40: =concatenate(C40,right(D40,4)) -> 장시아6446 | F40: 920626 | G40: 2 | H40: - | I40: - | J40: 취소됨 | K40: 2025. 12. 08. 17:23:54 | L40: 본인 취소 요청 | M40: pending | N40: 70,000원 | O40: 기업은행 | P40: 20601857901052 | Q40: 장시아
...

Sheet 시스템입력용입금데이터
A1: 거래일시 | B1: 구분 | C1: 입금액 | D1: 거래 후 잔액 | E1: 거래점 | F1: 보낸분/받는분 | G1: 메모
A2: 2025.12.8 11:53 | C2: 70000 | E2: 신한투자 | F2: 김진자7591
A3: 2025.12.8 11:52 | C3: 35000 | E3: 임베디 | F3: 윤정희3055
A4: 2025.12.8 11:46 | C4: 35000 | E4: 임베디 | F4: 문채영0417
A5: 2025.12.8 10:20 | C5: 35000 | E5: 우만동 | F5: 맹주갑7627
A6: 2025.12.8 9:50 | C6: 70000 | E6: 하나은행 | F6: 조용훈6725
A7: 2025.12.8 8:04 | C7: 35000 | E7: 신사동 | F7: 장재욱2348
A8: 2025.12.8 7:31 | C8: 70000 | E8: 새마을금 | F8: 이명희8150
A9: 2025.12.8 7:25 | C9: 35000 | E9: 석촌동 | F9: 이경훈7083
A10: 2025.12.8 3:52 | C10: 35000 | E10: 농협 | F10: 민영훈3412
A11: 2025.12.8 3:05 | C11: 35000 | E11: 우체국 | F11: 김규리9577
A12: 2025.12.7 23:05 | C12: 35000 | E12: 카뱅 | F12: 원종명7426
A13: 2025.12.7 22:25 | C13: 35000 | E13: 토스뱅크 | F13: 강효란2399
... A514: 2025.12.7 9:13 | C514: 70000 | E514: 농협 | F514: 김소옥7139
A515: 2025.12.7 9:13 | C515: 35000 | E515: 하나은행 | F515: 1115
A516: 2025.12.7 9:13 | C516: 70000 | E516: 하나은행 | F516: 장혜원5388
A517: 2025.12.7 9:13 | C517: 35000 | E517: 하나은행 | F517: 김순애 2928
A518: 2025.12.7 9:13 | C518: 35000 | E518: 하나은행 | F518: 문영희1684
A519: 2025.12.7 9:13 | C519: 35000 | E519: 하나은행 | F519: 송영미
A520: 2025.12.7 9:13 | C520: 35000 | E520: 미래에셋 | F520: 권혜주7104
A521: 2025.12.7 9:13 | C521: 35000 | E521: 중소기업 | F521: 김지만2399
A522: 2025.12.7 9:13 | C522: 35000 | E522: 하나은행 | F522: 조은경
A523: 2025.12.7 9:13 | C523: 70000 | E523: 농협 | F523: 송영희5681
A524: 2025.12.7 9:13 | C524: 35000 | E524: 하나은행 | F524: 김안나6030
A525: 2025.12.7 9:13 | C525: 35000 | E525: 하나은행 | F525: 오현희3509
A526: 2025.12.7 9:13 | C526: 70000 | E526: 부산은행 | F526: 박영철
A527: 2025.12.7 9:13 | C527: 70000 | E527: 우리은행 | F527: 현해시5421
... A577: 2025.12.7 9:12 | C577: 70000 | E577: 농협 | F577: 김희경5597
A578: 2025.12.7 9:12 | C578: 35000 | E578: 하나은행 | F578: 9091
A579: 2025.12.7 9:12 | C579: 35000 | E579: 농협 | F579: 박정민
A580: 2025.12.7 9:12 | C580: 35000 | E580: 독산동 | F580: 황은화0793
A581: 2025.12.7 9:12 | C581: 70000 | E581: 기장점 | F581: 윤달미
A582: 2025.12.7 9:12 | C582: 70000 | E582: 우리은행 | F582: 최선경1465
A583: 2025.12.7 9:12 | C583: 35000 | E583: 하나은행 | F583: 변수만
A584: 2025.12.7 9:12 | C584: 35000 | E584: 하나은행 | F584: 임상빈0952
A585: 2025.12.7 9:12 | C585: 70000 | E585: 농협 | F585: 6530이춘희
A586: 2025.12.7 9:12 | C586: 70000 | E586: 농협 | F586: 김경순
A587: 2025.12.7 9:12 | C587: 70000 | E587: 신한은행 | F587: 노주원1954
A588: 2025.12.7 9:12 | C588: 35000 | E588: 토스뱅크 | F588: 우진희6680
A589: 2025.12.7 9:12 | C589: 35000 | E589: 증권타 | F589: 류재관8774
...

Sheet 오픈이전 환불자 명단
A1: 연번 | B1: 이름 | C1: 전화번호 | D1: 이름(식별번호) | E1: 은행 | F1: 계좌번호 | G1: 예금주 | H1: 입금액 | I1: 환불완료여부
A2: =row()-1 -> 1 | B2: 민진영 | C2: 010-3387-1360 | D2: 민진영1360 | E2: 국민 | F2: 603702-0400-1677 | G2: 민진영 | H2: 70,000원 | I2: 완료
A3: =row()-1 -> 2 | B3: 김보람 | C3: 010-5051-0060 | D3: 김보람0060 | E3: 국민 | F3: 671-0020-405-0135 | G3: 김보람 | H3: 70,000원 | I3: 완료
A4: =row()-1 -> 3 | B4: 강현순 | C4: 010-6243-3573 | D4: 강현순3573 | E4: 국민 | F4: 575701-01-156681 | G4: 강현순 | H4: 70,000원 | I4: 완료
A5: =row()-1 -> 4 | B5: 고수경 | C5: 010-7101-4906 | D5: 고수경4906 | E5: 국민 | F5: 763801-00-212611 | G5: 고수경 | H5: 70,000원 | I5: 완료
A6: =row()-1 -> 5 | B6: 강은숙 | C6: 010-8999-2920 | D6: 강은숙 | E6: 국민 | F6: 815-24-0022-382 | G6: 강은숙 | H6: 70,000원 | I6: 완료
A7: =row()-1 -> 6 | B7: 이봉희 | C7: 010-9776-7352 | D7: 이봉희 | E7: 국민 | F7: 024802-04-254162 | G7: 이봉희 | H7: 70,000원 | I7: 완료
A8: =row()-1 -> 7 | B8: 손시연 | C8: 010-9950-5851 | D8: 손시연 | E8: 기업 | F8: 010-9950-5851 | G8: 손시연 | H8: 35,000원 | I8: 완료
